Workbook

Sheet Sheet1
C1: ■ 본공사 자재 입.출고 현황 (Status of main construction materials) | I1: Current status of Doosan | O1: ※ Update every Sunday!!
C2: 【Project : El-Dabaa Nuclear Power Plant (ENPP) #1 to 4】 | T2: =TODAY() -> 46161
B3: Code | C3: No | D3: Sortation | E3: Material No. | F3: Items / Services | G3: Size | H3: Unit | I3: DOOSAN | O3: DAESUN | T3: Remarks | U3: BALANCE IN REALITY | V3: PCS | W3: DATE
I4: Purchase | J4: Incoming | K4: Not come | L4: Other company | M4: Handover | N4: Balance | O4: Incoming | P4: Install | Q4: Fabrication | R4: Scrap/ Faulty | S4: Balance
A5: 1 | C5: A | E5: Grounding
A6: 9 | B6: GR001 | C6: 1 | D6: Ground | E6: Ground Cable 78SQ | F6: Ground Cable | G6: 78SQ | H6: M | I6: 17500 | J6: =SUMIFS('[1]POR Control Log-income'!L:L,'[1]POR Control Log-income'!F:F,[1]본공사입.출고현황!B6) -> 17200 | K6: =I6-J6 -> 300 | L6: 300 | M6: =SUMIFS('[1]POR Control Log-income'!L:L,'[1]POR Control Log-income'!F:F,[1]본공사입.출고현황!B6) -> 17200 | N6: =J6-M6 -> 0 | O6: =M6 -> 17200 | P6: 14128.1 | R6: 872.4 | S6: =O6-Q6-R6-P6 -> 2199.5 | U6: UNCOUNTABLE | V6: UNCOUNTABLE | W6: 16/5/2026
A7: 3 | B7: GR002 | C7: 2 | D7: Ground | E7: Ground Cable 70SQ | F7: Ground Cable | G7: 70SQ | H7: M | I7: 3120 | J7: =SUMIFS('[1]POR Control Log-income'!L:L,'[1]POR Control Log-income'!F:F,[1]본공사입.출고현황!B7) -> 3120 | K7: =I7-J7 -> 0 | M7: =SUMIFS('[1]POR Control Log-income'!L:L,'[1]POR Control Log-income'!F:F,[1]본공사입.출고현황!B7) -> 3120 | N7: =J7-M7 -> 0 | O7: =M7 -> 3120 | P7: =SUMIFS('[1]POR Control Log-out'!L:L,'[1]POR Control Log-out'!D:D,[1]본공사입.출고현황!B7) -> 258 | R7: 0 | S7: =O7-Q7-R7-P7 -> 2862 | U7: UNCOUNTABLE | V7: UNCOUNTABLE | W7: 16/5/2026
A8: 4 | B8: GR003 | C8: 3 | D8: Ground Fitting | E8: Ground TERMINAL LUG 70mm2 | F8: Terminal Lug | G8: 70mm2 | H8: EA | I8: 200 | J8: =SUMIFS('[1]POR Control Log-income'!L:L,'[1]POR Control Log-income'!F:F,[1]본공사입.출고현황!B8) -> 200 | K8: =I8-J8 -> 0 | M8: =SUMIFS('[1]POR Control Log-income'!L:L,'[1]POR Control Log-income'!F:F,[1]본공사입.출고현황!B8) -> 200 | N8: =J8-M8 -> 0 | O8: =M8 -> 200 | S8: =O8-Q8-R8-P8 -> 200 | U8: 200 | V8: 200 | W8: 16/5/2026
A9: 5 | B9: GR004 | C9: 4 | D9: Ground | E9: Cadweld Powder #90 | F9: Cadweld Powder | G9: #90 | H9: EA | I9: 100 | J9: =SUMIFS('[1]POR Control Log-income'!L:L,'[1]POR Control Log-income'!F:F,[1]본공사입.출고현황!B9) -> 100 | K9: =I9-J9 -> 0 | M9: =SUMIFS('[1]POR Control Log-income'!L:L,'[1]POR Control Log-income'!F:F,[1]본공사입.출고현황!B9) -> 100 | N9: =J9-M9 -> 0 | O9: =M9 -> 100 | P9: =SUMIFS('[1]POR Control Log-out'!L:L,'[1]POR Control Log-out'!D:D,[1]본공사입.출고현황!B9) -> 5 | R9: 2 | S9: =O9-Q9-R9-P9 -> 93 | U9: 100 | V9: 100 | W9: 16/5/2026
A10: 6 | B10: GR005 | C10: 5 | D10: Ground | E10: Cadweld Powder #115 | F10: Cadweld Powder | G10: #115 | H10: EA | I10: 540 | J10: =SUMIFS('[1]POR Control Log-income'!L:L,'[1]POR Control Log-income'!F:F,[1]본공사입.출고현황!B10) -> 540 | K10: =I10-J10 -> 0 | M10: =SUMIFS('[1]POR Control Log-income'!L:L,'[1]POR Control Log-income'!F:F,[1]본공사입.출고현황!B10) -> 540 | N10: =J10-M10 -> 0 | O10: =M10 -> 540 | P10: 201 | R10: 16 | S10: =O10-Q10-R10-P10 -> 323 | U10: 350 | V10: 350 | W10: 16/5/2026
A11: 7 | B11: GR006 | C11: 6 | D11: Ground | E11: Cadweld Powder #150 | F11: Cadweld Powder | G11: #150 | H11: EA | I11: 100 | J11: =SUMIFS('[1]POR Control Log-income'!L:L,'[1]POR Control Log-income'!F:F,[1]본공사입.출고현황!B11) -> 100 | K11: =I11-J11 -> 0 | M11: =SUMIFS('[1]POR Control Log-income'!L:L,'[1]POR Control Log-income'!F:F,[1]본공사입.출고현황!B11) -> 100 | N11: =J11-M11 -> 0 | O11: =M11 -> 100 | S11: =O11-Q11-R11-P11 -> 100 | U11: 100 | V11: 100 | W11: 16/5/2026
A12: 8 | B12: GR007 | C12: 7 | D12: Ground | E12: Cadweld Powder #200 | F12: Cadweld Powder | G12: #200 | H12: EA | I12: 1332 | J12: =SUMIFS('[1]POR Control Log-income'!L:L,'[1]POR Control Log-income'!F:F,[1]본공사입.출고현황!B12) -> 1332 | K12: =I12-J12 -> 0 | M12: =SUMIFS('[1]POR Control Log-income'!L:L,'[1]POR Control Log-income'!F:F,[1]본공사입.출고현황!B12) -> 1332 | N12: =J12-M12 -> 0 | O12: =M12 -> 1332 | P12: =SUMIFS('[1]POR Control Log-out'!L:L,'[1]POR Control Log-out'!D:D,[1]본공사입.출고현황!B12) -> 742 | R12: 223 | S12: =O12-Q12-R12-P12 -> 367 | U12: 380 | V12: 380 | W12: 16/5/2026
A13: 9 | B13: GR008 | C13: 8 | D13: Ground | E13: Cadweld XBQ-Y4Y4 | F13: Welding Mold | G13: Cross (+) | H13: EA | I13: 30 | J13: =SUMIFS('[1]POR Control Log-income'!L:L,'[1]POR Control Log-income'!F:F,[1]본공사입.출고현황!B13) -> 30 | K13: =I13-J13 -> 0 | M13: =SUMIFS('[1]POR Control Log-income'!L:L,'[1]POR Control Log-income'!F:F,[1]본공사입.출고현황!B13) -> 30 | N13: =J13-M13 -> 0 | O13: =M13 -> 30 | P13: =SUMIFS('[1]POR Control Log-out'!L:L,'[1]POR Control Log-out'!D:D,[1]본공사입.출고현황!B13) -> 13 | S13: =O13-Q13-R13-P13 -> 17 | U13: 17 | V13: 17 | W13: 16/5/2026
A14: 10 | B14: GR009 | C14: 9 | D14: Ground | E14: Cadweld PGC-Y4Y4 | F14: Welding Mold | G14: Parallel (=) | H14: EA | I14: 12 | J14: =SUMIFS('[1]POR Control Log-income'!L:L,'[1]POR Control Log-income'!F:F,[1]본공사입.출고현황!B14) -> 12 | K14: =I14-J14 -> 0 | M14: =SUMIFS('[1]POR Control Log-income'!L:L,'[1]POR Control Log-income'!F:F,[1]본공사입.출고현황!B14) -> 12 | N14: =J14-M14 -> 0 | O14: =M14 -> 12 | P14: =SUMIFS('[1]POR Control Log-out'!L:L,'[1]POR Control Log-out'!D:D,[1]본공사입.출고현황!B14) -> 3 | R14: 0 | S14: =O14-Q14-R14-P14 -> 9 | U14: 6 | V14: 6 | W14: 16/5/2026
A15: 11 | B15: GR010 | C15: 10 | D15: Ground | E15: Cadweld TAC-Y4Y4 | F15: Welding Mold | G15: Cross (T) | H15: EA | I15: 5 | J15: =SUMIFS('[1]POR Control Log-income'!L:L,'[1]POR Control Log-income'!F:F,[1]본공사입.출고현황!B15) -> 5 | K15: =I15-J15 -> 0 | M15: =SUMIFS('[1]POR Control Log-income'!L:L,'[1]POR Control Log-income'!F:F,[1]본공사입.출고현황!B15) -> 5 | N15: =J15-M15 -> 0 | O15: =M15 -> 5 | P15: =SUMIFS('[1]POR Control Log-out'!L:L,'[1]POR Control Log-out'!D:D,[1]본공사입.출고현황!B15) -> 1 | R15: 0 | S15: =O15-Q15-R15-P15 -> 4 | U15: 4 | V15: 4 | W15: 16/5/2026
A16: 12 | B16: GR011 | C16: 11 | D16: Ground | E16: Zinc Spray | F16: Zinc Spray | H16: EA | I16: 196 | J16: =SUMIFS('[1]POR Control Log-income'!L:L,'[1]POR Control Log-income'!F:F,[1]본공사입.출고현황!B16) -> 196 | K16: =I16-J16 -> 0 | M16: =SUMIFS('[1]POR Control Log-income'!L:L,'[1]POR Control Log-income'!F:F,[1]본공사입.출고현황!B16) -> 196 | N16: =J16-M16 -> 0 | O16: =M16 -> 196 | P16: =SUMIFS('[1]POR Control Log-out'!L:L,'[1]POR Control Log-out'!D:D,[1]본공사입.출고현황!B16) -> 99 | S16: =O16-Q16-R16-P16 -> 97 | U16: 84 | V16: 84 | W16: 16/5/2026
A17: 13 | B17: GR012 | C17: 12 | D17: Miscellious | E17: Nicoband | F17: Nicoband | G17: 10m x 15cm | H17: EA | I17: =20+750 -> 770 | J17: =SUMIFS('[1]POR Control Log-income'!L:L,'[1]POR Control Log-income'!F:F,[1]본공사입.출고현황!B17) -> 20 | K17: =I17-J17 -> 750 | M17: =SUMIFS('[1]POR Control Log-income'!L:L,'[1]POR Control Log-income'!F:F,[1]본공사입.출고현황!B17) -> 20 | N17: =J17-M17 -> 0 | O17: =M17 -> 20 | P17: 6 | R17: 0 | S17: =O17-Q17-R17-P17 -> 14 | W17: 16/5/2026
A18: 14 | B18: GR013 | C18: 13 | D18: Ground Conduit | E18: Flexible Conduit 2" | F18: Ground Conduit | G18: 2" | H18: M | I18: 2200 | J18: =SUMIFS('[1]POR Control Log-income'!L:L,'[1]POR Control Log-income'!F:F,[1]본공사입.출고현황!B18) -> 2200 | K18: =I18-J18 -> 0 | M18: =SUMIFS('[1]POR Control Log-income'!L:L,'[1]POR Control Log-income'!F:F,[1]본공사입.출고현황!B18) -> 2200 | N18: =J18-M18 -> 0 | O18: 2200 | P18: =SUMIFS('[1]POR Control Log-out'!L:L,'[1]POR Control Log-out'!D:D,[1]본공사입.출고현황!B18) -> 859 | R18: 121 | S18: =O18-Q18-R18-P18 -> 1220 | V18: _ | W18: 16/5/2026
A19: 15 | B19: GR014 | C19: 14 | D19: PVC PIPE | E19: PVC Flexible Pipe ф 20 | F19: PVC PIPE | G19: ф20 | H19: M | I19: 140 | J19: =SUMIFS('[1]POR Control Log-income'!L:L,'[1]POR Control Log-income'!F:F,[1]본공사입.출고현황!B19) -> 140 | K19: =I19-J19 -> 0 | M19: =SUMIFS('[1]POR Control Log-income'!L:L,'[1]POR Control Log-income'!F:F,[1]본공사입.출고현황!B19) -> 140 | N19: =J19-M19 -> 0 | O19: =M19 -> 140 | P19: =SUMIFS('[1]POR Control Log-out'!L:L,'[1]POR Control Log-out'!D:D,[1]본공사입.출고현황!B19) -> 0 | R19: 0 | S19: =O19-Q19-R19-P19 -> 140 | U19: 100 + SMALL PCS | V19: _ | W19: 16/5/2026
A20: 16 | B20: GR015 | C20: 15 | D20: Ground | E20: nVent Exothemic Welding Control Unit | F20: CAD WELD GUN | H20: EA | I20: 3 | J20: =SUMIFS('[1]POR Control Log-income'!L:L,'[1]POR Control Log-income'!F:F,[1]본공사입.출고현황!B20) -> 3 | K20: =I20-J20 -> 0 | M20: =SUMIFS('[1]POR Control Log-income'!L:L,'[1]POR Control Log-income'!F:F,[1]본공사입.출고현황!B20) -> 3 | N20: =J20-M20 -> 0 | O20: =M20 -> 3 | P20: =SUMIFS('[1]POR Control Log-out'!L:L,'[1]POR Control Log-out'!D:D,[1]본공사입.출고현황!B20) -> 2 | R20: 0 | S20: =O20-Q20-R20-P20 -> 1 | U20: 1 | V20: 1 | W20: 16/5/2026
A21: 17 | C21: B | E21: Conduit | J21: =SUMIFS('[1]POR Control Log-income'!L:L,'[1]POR Control Log-income'!F:F,[1]본공사입.출고현황!B21) -> 0 | M21: =SUMIFS('[1]POR Control Log-income'!L:L,'[1]POR Control Log-income'!F:F,[1]본공사입.출고현황!B21) -> 0 | N21: =J21-M21 -> 0 | S21: _ | W21: 16/5/2026
A22: 18 | B22: CO001 | C22: 1 | D22: Conduit | E22: Conduit (Galvanized) Ts-100x4.5 | F22: Conduit (Galvanized) | G22: 114x4.5 | H22: M | I22: 2437 | J22: =SUMIFS('[1]POR Control Log-income'!L:L,'[1]POR Control Log-income'!F:F,[1]본공사입.출고현황!B22) -> 2437 | K22: =I22-J22 -> 0 | M22: =SUMIFS('[1]POR Control Log-income'!L:L,'[1]POR Control Log-income'!F:F,[1]본공사입.출고현황!B22) -> 2437 | N22: =J22-M22 -> 0 | O22: =M22 -> 2437 | P22: =SUMIFS('[1]POR Control Log-out'!L:L,'[1]POR Control Log-out'!D:D,[1]본공사입.출고현황!B22) -> 1438 | Q22: =311+97 -> 408 | R22: 255 | S22: =O22-Q22-R22-P22 -> 336 | U22: 130 | V22: 13×12M | W22: 16/5/2026
A23: 19 | B23: CO002 | C23: 2 | D23: Conduit | E23: Conduit (Galvanized) Ts-80x4 | F23: Conduit (Galvanized) | G23: 88x4 | H23: M | I23: 5390 | J23: =SUMIFS('[1]POR Control Log-income'!L:L,'[1]POR Control Log-income'!F:F,[1]본공사입.출고현황!B23) -> 5390 | K23: =I23-J23 -> 0 | M23: =SUMIFS('[1]POR Control Log-income'!L:L,'[1]POR Control Log-income'!F:F,[1]본공사입.출고현황!B23) -> 5390 | N23: =J23-M23 -> 0 | O23: =M23 -> 5390 | P23: =SUMIFS('[1]POR Control Log-out'!L:L,'[1]POR Control Log-out'!D:D,[1]본공사입.출고현황!B23) -> 1452 | Q23: =198+58-120+240 -> 376 | R23: 238 | S23: =O23-Q23-R23-P23 -> 3324 | T23: ULD 및 UGD 필요수량 포함 | U23: 2964+ SMALL PCS | V23: 60+60+34+67+26×12M | W23: 16/5/2026
A24: 20 | B24: XX-CO003 | C24: 3 | D24: Conduit | E24: Conduit 159x4.5 | F24: Conduit | G24: 159x6.0 | H24: M | I24: 0 | J24: =SUMIFS('[1]POR Control Log-income'!L:L,'[1]POR Control Log-income'!F:F,[1]본공사입.출고현황!B24) -> 0 | K24: =I24-J24 -> 0 | M24: =SUMIFS('[1]POR Control Log-income'!L:L,'[1]POR Control Log-income'!F:F,[1]본공사입.출고현황!B24) -> 0 | N24: =J24-M24 -> 0 | O24: =M24 -> 0 | P24: =SUMIFS('[1]POR Control Log-out'!L:L,'[1]POR Control Log-out'!D:D,[1]본공사입.출고현황!B24) -> 0 | S24: _ | T24: 설계 변경 → 6.5"(168mm) | W24: 16/5/2026
A25: 25 | B25: CO003 | C25: 4 | D25: Conduit | E25: Conduit (Galvanized) 168x6 | F25: Conduit (Galvanized) | G25: 168x6 | H25: M | I25: 172 | J25: =SUMIFS('[1]POR Control Log-income'!L:L,'[1]POR Control Log-income'!F:F,[1]본공사입.출고현황!B25) -> 172 | K25: =I25-J25 -> 0 | M25: =SUMIFS('[1]POR Control Log-income'!L:L,'[1]POR Control Log-income'!F:F,[1]본공사입.출고현황!B25) -> 172 | N25: =J25-M25 -> 0 | O25: =M25 -> 172 | P25: =SUMIFS('[1]POR Control Log-out'!L:L,'[1]POR Control Log-out'!D:D,[1]본공사입.출고현황!B25) -> 0 | R25: 0 | S25: =O25-Q25-R25-P25 -> 172 | T25: 설계 추가 | U25: 156+ SMALL PCS | V25: 13 PCS×12M | W25: 16/5/2026
A26: 21 | B26: CO004 | C26: 5 | D26: Conduit | E26: Conduit 159x4.5 | F26: Conduit | G26: 159x4.5 | H26: M | I26: 1400.32 | J26: =SUMIFS('[1]POR Control Log-income'!L:L,'[1]POR Control Log-income'!F:F,[1]본공사입.출고현황!B26) -> 1400.32 | K26: =I26-J26 -> 0 | M26: =SUMIFS('[1]POR Control Log-income'!L:L,'[1]POR Control Log-income'!F:F,[1]본공사입.출고현황!B26) -> 1400.32 | N26: =J26-M26 -> 0 | O26: =M26 -> 1400.32 | P26: =SUMIFS('[1]POR Control Log-out'!L:L,'[1]POR Control Log-out'!D:D,[1]본공사입.출고현황!B26) -> 1176 | R26: 116.32 | S26: =O26-Q26-R26-P26 -> 108 | W26: 16/5/2026
A27: 22 | B27: CO005 | C27: 6 | D27: Conduit | E27: Conduit (Galvanized) 140x5 | F27: Conduit (Galvanized) | G27: 140x5 | H27: M | I27: 530 | J27: =SUMIFS('[1]POR Control Log-income'!L:L,'[1]POR Control Log-income'!F:F,[1]본공사입.출고현황!B27) -> 530 | K27: =I27-J27 -> 0 | M27: =SUMIFS('[1]POR Control Log-income'!L:L,'[1]POR Control Log-income'!F:F,[1]본공사입.출고현황!B27) -> 530 | N27: =J27-M27 -> 0 | O27: =M27 -> 530 | P27: =SUMIFS('[1]POR Control Log-out'!L:L,'[1]POR Control Log-out'!D:D,[1]본공사입.출고현황!B27) -> 0 | Q27: 189 | R27: 0 | S27: =O27-Q27-R27-P27 -> 341 | U27: 430 | V27: 43×10M | W27: 16/5/2026
A28: 23 | B28: XX-CO006 | C28: 7 | D28: Conduit | E28: Conduit 108x5 | F28: Conduit | G28: 108x5 | H28: M | I28: 0 | J28: =SUMIFS('[1]POR Control Log-income'!L:L,'[1]POR Control Log-income'!F:F,[1]본공사입.출고현황!B28) -> 0 | K28: =I28-J28 -> 0 | M28: =SUMIFS('[1]POR Control Log-income'!L:L,'[1]POR Control Log-income'!F:F,[1]본공사입.출고현황!B28) -> 0 | N28: =J28-M28 -> 0 | O28: =M28 -> 0 | P28: =SUMIFS('[1]POR Control Log-out'!L:L,'[1]POR Control Log-out'!D:D,[1]본공사입.출고현황!B28) -> 0 | R28: 0 | S28: _ | T28: 설계 삭제(토건 역무) | W28: 16/5/2026
A29: 24 | B29: CO007 | C29: 8 | D29: Conduit | E29: Conduit 108x4.0 | F29: Conduit | G29: 108x4 | H29: M | I29: =5956+84 -> 6040 | J29: =SUMIFS('[1]POR Control Log-income'!L:L,'[1]POR Control Log-income'!F:F,[1]본공사입.출고현황!B29) -> 5956 | K29: =I29-J29 -> 84 | L29: 66 | M29: =SUMIFS('[1]POR Control Log-income'!L:L,'[1]POR Control Log-income'!F:F,[1]본공사입.출고현황!B29) -> 5956 | N29: =J29-M29 -> 0 | O29: =M29 -> 5956 | P29: =SUMIFS('[1]POR Control Log-out'!L:L,'[1]POR Control Log-out'!D:D,[1]본공사입.출고현황!B29) -> 5156.488 | Q29: 113 | R29: =555.512 -> 555.512 | S29: =O29-Q29-R29-P29 -> 131 | T29: (Scrap 555.5)-(발전기 굴뚝 : 86M) | U29: 150 + SMALL PCS | V29: 15×10M | W29: 16/5/2026
A30: 25 | B30: CO008.1 | C30: 9 | D30: Conduit | E30: Conduit (Galvanized) 60.3x3.91 | F30: Conduit (Galvanized) | G30: 60.3x3.91 | H30: M | I30: 18 | J30: =SUMIFS('[1]POR Control Log-income'!L:L,'[1]POR Control Log-income'!F:F,[1]본공사입.출고현황!B30) -> 18 | K30: =I30-J30 -> 0 | M30: =SUMIFS('[1]POR Control Log-income'!L:L,'[1]POR Control Log-income'!F:F,[1]본공사입.출고현황!B30) -> 18 | N30: =J30-M30 -> 0 | O30: =M30 -> 18 | P30: =SUMIFS('[1]POR Control Log-out'!L:L,'[1]POR Control Log-out'!D:D,[1]본공사입.출고현황!B30) -> 0 | Q30: 0 | R30: 0 | S30: =O30-Q30-R30-P30 -> 18 | T30: 추가 | W30: 16/5/2026
A31: 26 | B31: CO009 | C31: 10 | D31: Conduit Fitting | E31: Conduit Coupling 168x4 | F31: Conduit Coupling | G31: 168x4 | H31: M | I31: 44 | J31: =SUMIFS('[1]POR Control Log-income'!L:L,'[1]POR Control Log-income'!F:F,[1]본공사입.출고현황!B31) -> 44 | K31: =I31-J31 -> 0 | M31: =SUMIFS('[1]POR Control Log-income'!L:L,'[1]POR Control Log-income'!F:F,[1]본공사입.출고현황!B31) -> 44 | N31: =J31-M31 -> 0 | O31: =M31 -> 44 | P31: =SUMIFS('[1]POR Control Log-out'!L:L,'[1]POR Control Log-out'!D:D,[1]본공사입.출고현황!B31) -> 1.3 | R31: 0 | S31: =O31-Q31-R31-P31 -> 42.7 | T31: =S31/0.15 -> 284.66667 | U31: 336(160 RETURNED TO DOOSAN) | V31: 241 IN WARHOUSE+95 INSTALLED | W31: 16/5/2026
A32: 27 | B32: CO010 | C32: 11 | D32: Conduit Fitting | E32: Conduit Coupling 168x4 | F32: Conduit Coupling | G32: 168x4 | H32: EA | I32: 200 | J32: =SUMIFS('[1]POR Control Log-income'!L:L,'[1]POR Control Log-income'!F:F,[1]본공사입.출고현황!B32) -> 200 | K32: =I32-J32 -> 0 | M32: =SUMIFS('[1]POR Control Log-income'!L:L,'[1]POR Control Log-income'!F:F,[1]본공사입.출고현황!B32) -> 200 | N32: =J32-M32 -> 0 | O32: =M32 -> 200 | P32: =SUMIFS('[1]POR Control Log-out'!L:L,'[1]POR Control Log-out'!D:D,[1]본공사입.출고현황!B32) -> 188 | Q32: 0 | R32: 0 | S32: =O32-Q32-R32-P32 -> 12 | W32: 16/5/2026
A33: 28 | B33: CO011 | C33: 12 | D33: Conduit Fitting | E33: Conduit Coupling 125-Ts | F33: Conduit Coupling | G33: Ts-152x5 | H33: EA | I33: =60+60 -> 120 | J33: =SUMIFS('[1]POR Control Log-income'!L:L,'[1]POR Control Log-income'!F:F,[1]본공사입.출고현황!B33) -> 60 | K33: =I33-J33 -> 60 | M33: =SUMIFS('[1]POR Control Log-income'!L:L,'[1]POR Control Log-income'!F:F,[1]본공사입.출고현황!B33) -> 60 | N33: =J33-M33 -> 0 | O33: =M33 -> 60 | P33: =SUMIFS('[1]POR Control Log-out'!L:L,'[1]POR Control Log-out'!D:D,[1]본공사입.출고현황!B33) -> 0 | R33: 0 | S33: =O33-Q33-R33-P33 -> 60 | W33: 16/5/2026
A34: 29 | B34: CO012 | C34: 13 | D34: Conduit Fitting | E34: Conduit Coupling 121x5 | F34: Conduit Coupling | G34: 121x5 | H34: M | I34: 104 | J34: =SUMIFS('[1]POR Control Log-income'!L:L,'[1]POR Control Log-income'!F:F,[1]본공사입.출고현황!B34) -> 104 | K34: =I34-J34 -> 0 | M34: =SUMIFS('[1]POR Control Log-income'!L:L,'[1]POR Control Log-income'!F:F,[1]본공사입.출고현황!B34) -> 104 | N34: =J34-M34 -> 0 | O34: =M34 -> 104 | P34: =SUMIFS('[1]POR Control Log-out'!L:L,'[1]POR Control Log-out'!D:D,[1]본공사입.출고현황!B34) -> 48 | Q34: 1.5 | R34: 0 | S34: =O34-Q34-R34-P34 -> 54.5 | T34: =S34/0.15 -> 363.33333 | W34: 16/5/2026
A35: 30 | B35: CO013 | C35: 14 | D35: Conduit Fitting | E35: Conduit Coupling 121x5 | F35: Conduit Coupling | G35: 121x5 | H35: EA | I35: 456 | J35: =SUMIFS('[1]POR Control Log-income'!L:L,'[1]POR Control Log-income'!F:F,[1]본공사입.출고현황!B35) -> 456 | K35: =I35-J35 -> 0 | M35: =SUMIFS('[1]POR Control Log-income'!L:L,'[1]POR Control Log-income'!F:F,[1]본공사입.출고현황!B35) -> 456 | N35: =J35-M35 -> 0 | O35: =M35 -> 456 | P35: =SUMIFS('[1]POR Control Log-out'!L:L,'[1]POR Control Log-out'!D:D,[1]본공사입.출고현황!B35) -> 423 | Q35: 33 | R35: 0 | S35: _ | W35: 16/5/2026
A36: 31 | B36: CO014 | C36: 15 | D36: Conduit Fitting | E36: Conduit Coupling 100-Ts | F36: Conduit Coupling | G36: 100-Ts | H36: EA | I36: 280 | J36: =SUMIFS('[1]POR Control Log-income'!L:L,'[1]POR Control Log-income'!F:F,[1]본공사입.출고현황!B36) -> 280 | K36: =I36-J36 -> 0 | M36: =SUMIFS('[1]POR Control Log-income'!L:L,'[1]POR Control Log-income'!F:F,[1]본공사입.출고현황!B36) -> 280 | N36: =J36-M36 -> 0 | O36: =M36 -> 280 | P36: =SUMIFS('[1]POR Control Log-out'!L:L,'[1]POR Control Log-out'!D:D,[1]본공사입.출고현황!B36) -> 120 | Q36: 35 | R36: 0 | S36: =O36-Q36-R36-P36 -> 125 | W36: 16/5/2026
A37: 32 | B37: CO015 | C37: 16 | D37: Conduit Fitting | E37: Conduit Coupling 80-Ts | F37: Conduit Coupling | G37: 80-Ts | H37: EA | I37: 440 | J37: =SUMIFS('[1]POR Control Log-income'!L:L,'[1]POR Control Log-income'!F:F,[1]본공사입.출고현황!B37) -> 440 | K37: =I37-J37 -> 0 | M37: =SUMIFS('[1]POR Control Log-income'!L:L,'[1]POR Control Log-income'!F:F,[1]본공사입.출고현황!B37) -> 440 | N37: =J37-M37 -> 0 | O37: =M37 -> 440 | P37: =SUMIFS('[1]POR Control Log-out'!L:L,'[1]POR Control Log-out'!D:D,[1]본공사입.출고현황!B37) -> 97 | Q37: =23+21 -> 44 | R37: 0 | S37: =O37-Q37-R37-P37 -> 299 | W37: 16/5/2026
B38: CO015.1 | C38: 17 | D38: Conduit Fitting | E38: Conduit Coupling | F38: Conduit Coupling | G38: 50-11 NPT | H38: EA | I38: 9 | J38: =SUMIFS('[1]POR Control Log-income'!L:L,'[1]POR Control Log-income'!F:F,[1]본공사입.출고현황!B38) -> 9 | K38: =I38-J38 -> 0 | M38: =SUMIFS('[1]POR Control Log-income'!L:L,'[1]POR Control Log-income'!F:F,[1]본공사입.출고현황!B38) -> 9 | N38: =J38-M38 -> 0 | O38: =M38 -> 9 | P38: 9 | Q38: 0 | S38: _ | T38: 추가 | W38: 16/5/2026
A39: 33 | B39: CO016 | C39: 18 | D39: Sup't | E39: Angle 50x50x5 | F39: Angle | G39: 50*50*5 | H39: M | I39: 3968 | J39: =SUMIFS('[1]POR Control Log-income'!L:L,'[1]POR Control Log-income'!F:F,[1]본공사입.출고현황!B39) -> 3968 | K39: =I39-J39 -> 0 | M39: =SUMIFS('[1]POR Control Log-income'!L:L,'[1]POR Control Log-income'!F:F,[1]본공사입.출고현황!B39) -> 3968 | N39: =J39-M39 -> 0 | O39: =M39 -> 3968 | P39: =SUMIFS('[1]POR Control Log-out'!L:L,'[1]POR Control Log-out'!D:D,[1]본공사입.출고현황!B39) -> 2726 | Q39: =40.1+3 -> 43.1 | R39: =323.9+3 -> 326.9 | S39: =O39-Q39-R39-P39 -> 872 | T39: ULD 및 UGD 필요수량 포함 | U39: 466 | V39: 8×12M | W39: 16/5/2026
A40: 34 | B40: CO017 | C40: 19 | D40: Sup't | E40: Angle 70x70x7 | F40: Angle | G40: 70*70*7 | H40: M | I40: 732 | J40: =SUMIFS('[1]POR Control Log-income'!L:L,'[1]POR Control Log-income'!F:F,[1]본공사입.출고현황!B40) -> 732 | K40: =I40-J40 -> 0 | M40: =SUMIFS('[1]POR Control Log-income'!L:L,'[1]POR Control Log-income'!F:F,[1]본공사입.출고현황!B40) -> 732 | N40: =J40-M40 -> 0 | O40: =M40 -> 732 | P40: =SUMIFS('[1]POR Control Log-out'!L:L,'[1]POR Control Log-out'!D:D,[1]본공사입.출고현황!B40) -> 414.4 | R40: 29.6 | S40: =O40-Q40-R40-P40 -> 288 | U40: 288 | V40: 24×12M | W40: 16/5/2026
...
