Workbook

Sheet 본공사입.출고현황
C1: ■ 본공사 자재 입.출고 현황 (Status of main construction materials) | I1: Current status of Doosan | O1: ※ Update every Sunday!!
C2: 【Project : El-Dabaa Nuclear Power Plant (ENPP) #1 to 4】 | T2: =TODAY() -> 46174
B3: Code | C3: No | D3: Sortation | E3: Material No. | F3: Items / Services | G3: Size | H3: Unit | I3: DOOSAN | O3: DAESUN | T3: Remarks | V3: Description | W3: Size | X3: Unit | AC3: installed | AG3: 실재고와 차이 | AI3: Checking of Balance
I4: Purchase | J4: Incoming | K4: Not come | L4: Other company | M4: Handover | N4: Balance | O4: Incoming | P4: Install | Q4: Fabrication | R4: Scrap/ Faulty | S4: Balance | AI4: 45759 | AJ4: 45764 | AK4: 45772 | AL4: 45777 | AM4: 45787 | AN4: 45792 | AO4: 45801 | AP4: 45806 | AQ4: 45820 | AR4: 45829 | AS4: 45837 | AT4: 45843 | AU4: 45851 | AV4: 45857 | AW4: 45865 | AX4: 45871 | AY4: 45876 | AZ4: 45885 | BA4: 45890 | BB4: 45896 | BC4: 45904 | BD4: 45912 | BE4: 45918 | BF4: 45927 | BG4: 45929 | BH4: 45932 | BI4: 45941 | BJ4: 45946 | BK4: 45955 | BL4: 45960 | BM4: 45969 | BN4: 45974 | BO4: 45983 | BP4: 45988 | BQ4: 45997 | BR4: 46002 | BS4: 46011 | BT4: 46023 | BU4: 46029 | BV4: 46036 | BW4: 46078 | BX4: 46085
A5: 1 | C5: A | E5: Grounding | AG5: =BI5-S5 -> 0
A6: 9 | B6: GR001 | C6: 1 | D6: Ground | E6: Ground Cable 78SQ | F6: Ground Cable | G6: 78SQ | H6: M | I6: 17500 | J6: =SUMIFS('POR Control Log-income'!L:L,'POR Control Log-income'!F:F,본공사입.출고현황!B6) -> 17200 | K6: =I6-J6 -> 300 | L6: 300 | M6: =SUMIFS('POR Control Log-income'!L:L,'POR Control Log-income'!F:F,본공사입.출고현황!B6) -> 17200 | N6: =J6-M6 -> 0 | O6: =M6 -> 17200 | P6: =SUMIFS('POR Control Log-out'!L:L,'POR Control Log-out'!D:D,본공사입.출고현황!B6) -> 14194.1 | R6: 872.4 | S6: =O6-Q6-R6-P6 -> 2133.5 | V6: Ground Cable | W6: 78SQ | X6: M | Y6: O | AC6: 13643.384 | AG6: =BM6-S6 -> -1281 | AI6: 1318 | AJ6: 1258 | AK6: 1258 | AL6: 1258 | AM6: 1223 | AN6: 1223 | AO6: 1223 | AP6: 1223 | AQ6: 1223 | AR6: 1223 | AS6: 1223 | AT6: 1110.5 | AU6: 1110.5 | AV6: 1110.5 | AW6: 1110.5 | AX6: 1065.5 | AY6: 977.5 | AZ6: 852.5 | BA6: 852.5 | BB6: 852.5 | BC6: 852.5 | BD6: 852.5 | BE6: 852.5 | BF6: 852.5 | BG6: 852.5 | BH6: 852.5 | BI6: 852.5 | BJ6: 852.5 | BK6: 852.5 | BL6: 852.5 | BM6: 852.5 | BN6: 852.5 | BO6: 852.5 | BP6: 852.5 | BQ6: 852.5 | BR6: 838.5 | BS6: 807 | BT6: 807 | BU6: 807 | BV6: 807 | BW6: 2252 | BX6: =BW6-BY6 -> 2246 | BY6: 6
A7: 3 | B7: GR002 | C7: 2 | D7: Ground | E7: Ground Cable 70SQ | F7: Ground Cable | G7: 70SQ | H7: M | I7: 3120 | J7: =SUMIFS('POR Control Log-income'!L:L,'POR Control Log-income'!F:F,본공사입.출고현황!B7) -> 3120 | K7: =I7-J7 -> 0 | M7: =SUMIFS('POR Control Log-income'!L:L,'POR Control Log-income'!F:F,본공사입.출고현황!B7) -> 3120 | N7: =J7-M7 -> 0 | O7: =M7 -> 3120 | P7: =SUMIFS('POR Control Log-out'!L:L,'POR Control Log-out'!D:D,본공사입.출고현황!B7) -> 258 | R7: 0 | S7: =O7-Q7-R7-P7 -> 2862 | V7: Ground Cable | W7: 70SQ | X7: M | Y7: O | AC7: 22.1 | AG7: =BM7-S7 -> 80 | AI7: 3120 | AK7: 3120 | AL7: 3120 | AM7: 3120 | AN7: 3120 | AO7: 3120 | AP7: 3068 | AQ7: 2942 | AR7: 2942 | AS7: 2942 | AT7: 2942 | AU7: 2942 | AV7: 2942 | AW7: 2942 | AX7: 2942 | AY7: 2942 | AZ7: 2942 | BA7: 2942 | BB7: 2942 | BC7: 2942 | BD7: 2942 | BE7: 2942 | BF7: 2942 | BG7: 2942 | BH7: 2942 | BI7: 2942 | BJ7: 2942 | BK7: 2942 | BL7: 2942 | BM7: 2942 | BN7: 2942 | BO7: 2942 | BP7: 2906 | BQ7: 2906 | BR7: 2906 | BS7: 2906 | BT7: 2906 | BU7: 2906 | BV7: 2906 | BW7: 2862 | BX7: =BW7-BY7 -> 2862
A8: 4 | B8: GR003 | C8: 3 | D8: Ground Fitting | E8: Ground TERMINAL LUG 70mm2 | F8: Terminal Lug | G8: 70mm2 | H8: EA | I8: 200 | J8: =SUMIFS('POR Control Log-income'!L:L,'POR Control Log-income'!F:F,본공사입.출고현황!B8) -> 200 | K8: =I8-J8 -> 0 | M8: =SUMIFS('POR Control Log-income'!L:L,'POR Control Log-income'!F:F,본공사입.출고현황!B8) -> 200 | N8: =J8-M8 -> 0 | O8: =M8 -> 200 | S8: =O8-Q8-R8-P8 -> 200 | V8: Ground TERMINAL LUG | W8: 70mm2 | X8: EA | Y8: O | AG8: =BM8-S8 -> -9 | AI8: 191 | AK8: 191 | AL8: 191 | AM8: 191 | AN8: 191 | AO8: 191 | AP8: 191 | AQ8: 191 | AR8: 191 | AS8: 191 | AT8: 191 | AU8: 191 | AV8: 191 | AW8: 191 | AX8: 191 | AY8: 191 | AZ8: 191 | BA8: 191 | BB8: 191 | BC8: 191 | BD8: 191 | BE8: 191 | BF8: 191 | BG8: 191 | BH8: 191 | BI8: 191 | BJ8: 191 | BK8: 191 | BL8: 191 | BM8: 191 | BN8: 191 | BO8: 191 | BP8: 191 | BQ8: 191 | BR8: 191 | BS8: 191 | BT8: 191 | BU8: 191 | BV8: 191 | BW8: 200 | BX8: =BW8-BY8 -> 200
A9: 5 | B9: GR004 | C9: 4 | D9: Ground | E9: Cadweld Powder #90 | F9: Cadweld Powder | G9: #90 | H9: EA | I9: 100 | J9: =SUMIFS('POR Control Log-income'!L:L,'POR Control Log-income'!F:F,본공사입.출고현황!B9) -> 100 | K9: =I9-J9 -> 0 | M9: =SUMIFS('POR Control Log-income'!L:L,'POR Control Log-income'!F:F,본공사입.출고현황!B9) -> 100 | N9: =J9-M9 -> 0 | O9: =M9 -> 100 | P9: =SUMIFS('POR Control Log-out'!L:L,'POR Control Log-out'!D:D,본공사입.출고현황!B9) -> 5 | R9: 2 | S9: =O9-Q9-R9-P9 -> 93 | U9: 100 | V9: Cadweld Powder | W9: #90 | X9: EA | Y9: O | AC9: 4 | AG9: =BM9-S9 -> 0 | AI9: 97 | AK9: 97 | AL9: 97 | AM9: 97 | AN9: 97 | AO9: 97 | AP9: 97 | AQ9: 97 | AR9: 97 | AS9: 97 | AT9: 97 | AU9: 97 | AV9: 97 | AW9: 97 | AX9: 97 | AY9: 97 | AZ9: 97 | BA9: 97 | BB9: 93 | BC9: 93 | BD9: 93 | BE9: 93 | BF9: 93 | BG9: 93 | BH9: 93 | BI9: 93 | BJ9: 93 | BK9: 93 | BL9: 93 | BM9: 93 | BN9: 93 | BO9: 93 | BP9: 93 | BQ9: 93 | BR9: 93 | BS9: 93 | BT9: 93 | BU9: 93 | BV9: 93 | BW9: 93 | BX9: =BW9-BY9 -> 93
A10: 6 | B10: GR005 | C10: 5 | D10: Ground | E10: Cadweld Powder #115 | F10: Cadweld Powder | G10: #115 | H10: EA | I10: 540 | J10: =SUMIFS('POR Control Log-income'!L:L,'POR Control Log-income'!F:F,본공사입.출고현황!B10) -> 540 | K10: =I10-J10 -> 0 | M10: =SUMIFS('POR Control Log-income'!L:L,'POR Control Log-income'!F:F,본공사입.출고현황!B10) -> 540 | N10: =J10-M10 -> 0 | O10: =M10 -> 540 | P10: =SUMIFS('POR Control Log-out'!L:L,'POR Control Log-out'!D:D,본공사입.출고현황!B10) -> 207 | R10: 16 | S10: =O10-Q10-R10-P10 -> 317 | U10: 419 | V10: Cadweld Powder | W10: #115 | X10: EA | Y10: O | AC10: 151 | AD10: =O10-AC10 -> 389 | AG10: =BM10-S10 -> 47 | AI10: 414 | AK10: 414 | AL10: 414 | AM10: 414 | AN10: 414 | AO10: 414 | AP10: 404 | AQ10: 394 | AR10: 394 | AS10: 394 | AT10: 384 | AU10: 384 | AV10: 384 | AW10: 384 | AX10: 374 | AY10: 374 | AZ10: 374 | BA10: 364 | BB10: 364 | BC10: 364 | BD10: 364 | BE10: 364 | BF10: 364 | BG10: 364 | BH10: 364 | BI10: 364 | BJ10: 364 | BK10: 364 | BL10: 364 | BM10: 364 | BN10: 364 | BO10: 364 | BP10: 359 | BQ10: 359 | BR10: 357 | BS10: 347 | BT10: 347 | BU10: 347 | BV10: 347 | BW10: 337 | BX10: =BW10-BY10 -> 333 | BY10: 4
A11: 7 | B11: GR006 | C11: 6 | D11: Ground | E11: Cadweld Powder #150 | F11: Cadweld Powder | G11: #150 | H11: EA | I11: 100 | J11: =SUMIFS('POR Control Log-income'!L:L,'POR Control Log-income'!F:F,본공사입.출고현황!B11) -> 100 | K11: =I11-J11 -> 0 | M11: =SUMIFS('POR Control Log-income'!L:L,'POR Control Log-income'!F:F,본공사입.출고현황!B11) -> 100 | N11: =J11-M11 -> 0 | O11: =M11 -> 100 | S11: =O11-Q11-R11-P11 -> 100 | U11: 98 | V11: Cadweld Powder | W11: #150 | X11: EA | Y11: O | AG11: =BM11-S11 -> -2 | AI11: 98 | AK11: 98 | AL11: 98 | AM11: 98 | AN11: 98 | AO11: 98 | AP11: 98 | AQ11: 98 | AR11: 98 | AS11: 98 | AT11: 98 | AU11: 98 | AV11: 98 | AW11: 98 | AX11: 98 | AY11: 98 | AZ11: 98 | BA11: 98 | BB11: 98 | BC11: 98 | BD11: 98 | BE11: 98 | BF11: 98 | BG11: 98 | BH11: 98 | BI11: 98 | BJ11: 98 | BK11: 98 | BL11: 98 | BM11: 98 | BN11: 98 | BO11: 98 | BP11: 98 | BQ11: 98 | BR11: 98 | BS11: 98 | BT11: 98 | BU11: 98 | BV11: 98 | BW11: 100 | BX11: =BW11-BY11 -> 100
A12: 8 | B12: GR007 | C12: 7 | D12: Ground | E12: Cadweld Powder #200 | F12: Cadweld Powder | G12: #200 | H12: EA | I12: 1332 | J12: =SUMIFS('POR Control Log-income'!L:L,'POR Control Log-income'!F:F,본공사입.출고현황!B12) -> 1332 | K12: =I12-J12 -> 0 | M12: =SUMIFS('POR Control Log-income'!L:L,'POR Control Log-income'!F:F,본공사입.출고현황!B12) -> 1332 | N12: =J12-M12 -> 0 | O12: =M12 -> 1332 | P12: =SUMIFS('POR Control Log-out'!L:L,'POR Control Log-out'!D:D,본공사입.출고현황!B12) -> 742 | R12: 223 | S12: =O12-Q12-R12-P12 -> 367 | U12: 430 | V12: Cadweld Powder | W12: #200 | X12: EA | Y12: O | AC12: 740 | AG12: =BM12-S12 -> 2 | AI12: 410 | AJ12: 400 | AK12: 400 | AL12: 369 | AM12: 369 | AN12: 369 | AO12: 369 | AP12: 369 | AQ12: 369 | AR12: 369 | AS12: 369 | AT12: 369 | AU12: 369 | AV12: 369 | AW12: 369 | AX12: 369 | AY12: 369 | AZ12: 369 | BA12: 369 | BB12: 369 | BC12: 369 | BD12: 369 | BE12: 369 | BF12: 369 | BG12: 369 | BH12: 369 | BI12: 369 | BJ12: 369 | BK12: 369 | BL12: 369 | BM12: 369 | BN12: 369 | BO12: 369 | BP12: 369 | BQ12: 369 | BR12: 369 | BS12: 367 | BT12: 367 | BU12: 367 | BV12: 367 | BW12: 367 | BX12: =BW12-BY12 -> 367
A13: 9 | B13: GR008 | C13: 8 | D13: Ground | E13: Cadweld XBQ-Y4Y4 | F13: Welding Mold | G13: Cross (+) | H13: EA | I13: 30 | J13: =SUMIFS('POR Control Log-income'!L:L,'POR Control Log-income'!F:F,본공사입.출고현황!B13) -> 30 | K13: =I13-J13 -> 0 | M13: =SUMIFS('POR Control Log-income'!L:L,'POR Control Log-income'!F:F,본공사입.출고현황!B13) -> 30 | N13: =J13-M13 -> 0 | O13: =M13 -> 30 | P13: =SUMIFS('POR Control Log-out'!L:L,'POR Control Log-out'!D:D,본공사입.출고현황!B13) -> 13 | S13: =O13-Q13-R13-P13 -> 17 | U13: 19 | V13: Cadweld Mold | W13: Cross (+) | X13: EA | Y13: O | AG13: =BM13-S13 -> 1 | AI13: 18 | AK13: 18 | AL13: 18 | AM13: 18 | AN13: 18 | AO13: 18 | AP13: 18 | AQ13: 18 | AR13: 18 | AS13: 18 | AT13: 18 | AU13: 18 | AV13: 18 | AW13: 18 | AX13: 18 | AY13: 18 | AZ13: 18 | BA13: 18 | BB13: 18 | BC13: 18 | BD13: 18 | BE13: 18 | BF13: 18 | BG13: 18 | BH13: 18 | BI13: 18 | BJ13: 18 | BK13: 18 | BL13: 18 | BM13: 18 | BN13: 18 | BO13: 18 | BP13: 18 | BQ13: 18 | BR13: 18 | BS13: 18 | BT13: 18 | BU13: 18 | BV13: 18 | BW13: 17 | BX13: =BW13-BY13 -> 17
A14: 10 | B14: GR009 | C14: 9 | D14: Ground | E14: Cadweld PGC-Y4Y4 | F14: Welding Mold | G14: Parallel (=) | H14: EA | I14: 12 | J14: =SUMIFS('POR Control Log-income'!L:L,'POR Control Log-income'!F:F,본공사입.출고현황!B14) -> 12 | K14: =I14-J14 -> 0 | M14: =SUMIFS('POR Control Log-income'!L:L,'POR Control Log-income'!F:F,본공사입.출고현황!B14) -> 12 | N14: =J14-M14 -> 0 | O14: =M14 -> 12 | P14: =SUMIFS('POR Control Log-out'!L:L,'POR Control Log-out'!D:D,본공사입.출고현황!B14) -> 3 | R14: 0 | S14: =O14-Q14-R14-P14 -> 9 | U14: 7 | V14: Cadweld Mold | W14: Parallel (=) | X14: EA | Y14: O | AG14: =BM14-S14 -> 2 | AI14: 12 | AK14: 12 | AL14: 12 | AM14: 12 | AN14: 12 | AO14: 12 | AP14: 11 | AQ14: 11 | AR14: 11 | AS14: 11 | AT14: 11 | AU14: 11 | AV14: 11 | AW14: 11 | AX14: 11 | AY14: 11 | AZ14: 11 | BA14: 11 | BB14: 11 | BC14: 11 | BD14: 11 | BE14: 11 | BF14: 11 | BG14: 11 | BH14: 11 | BI14: 11 | BJ14: 11 | BK14: 11 | BL14: 11 | BM14: 11 | BN14: 11 | BO14: 11 | BP14: 10 | BQ14: 10 | BR14: 10 | BS14: 10 | BT14: 10 | BU14: 10 | BV14: 10 | BW14: 10 | BX14: =BW14-BY14 -> 10
A15: 11 | B15: GR010 | C15: 10 | D15: Ground | E15: Cadweld TAC-Y4Y4 | F15: Welding Mold | G15: Cross (T) | H15: EA | I15: 5 | J15: =SUMIFS('POR Control Log-income'!L:L,'POR Control Log-income'!F:F,본공사입.출고현황!B15) -> 5 | K15: =I15-J15 -> 0 | M15: =SUMIFS('POR Control Log-income'!L:L,'POR Control Log-income'!F:F,본공사입.출고현황!B15) -> 5 | N15: =J15-M15 -> 0 | O15: =M15 -> 5 | P15: =SUMIFS('POR Control Log-out'!L:L,'POR Control Log-out'!D:D,본공사입.출고현황!B15) -> 1 | R15: 0 | S15: =O15-Q15-R15-P15 -> 4 | U15: 9 | V15: Cadweld Mold | W15: Cross (T) | X15: EA | Y15: O | AG15: =BM15-S15 -> 0 | AI15: 4 | AK15: 4 | AL15: 4 | AM15: 4 | AN15: 4 | AO15: 4 | AP15: 4 | AQ15: 4 | AR15: 4 | AS15: 4 | AT15: 4 | AU15: 4 | AV15: 4 | AW15: 4 | AX15: 4 | AY15: 4 | AZ15: 4 | BA15: 4 | BB15: 4 | BC15: 4 | BD15: 4 | BE15: 4 | BF15: 4 | BG15: 4 | BH15: 4 | BI15: 4 | BJ15: 4 | BK15: 4 | BL15: 4 | BM15: 4 | BN15: 4 | BO15: 4 | BP15: 4 | BQ15: 4 | BR15: 4 | BS15: 4 | BT15: 4 | BU15: 4 | BV15: 4 | BW15: 4 | BX15: =BW15-BY15 -> 4
A16: 12 | B16: GR011 | C16: 11 | D16: Ground | E16: Zinc Spray | F16: Zinc Spray | H16: EA | I16: 196 | J16: =SUMIFS('POR Control Log-income'!L:L,'POR Control Log-income'!F:F,본공사입.출고현황!B16) -> 196 | K16: =I16-J16 -> 0 | M16: =SUMIFS('POR Control Log-income'!L:L,'POR Control Log-income'!F:F,본공사입.출고현황!B16) -> 196 | N16: =J16-M16 -> 0 | O16: =M16 -> 196 | P16: =SUMIFS('POR Control Log-out'!L:L,'POR Control Log-out'!D:D,본공사입.출고현황!B16) -> 99 | S16: =O16-Q16-R16-P16 -> 97 | U16: 128 | V16: Zinc Spray | X16: EA | AC16: 91 | AG16: =BM16-S16 -> 8 | AI16: 130 | AK16: 130 | AL16: 130 | AM16: 130 | AN16: 129 | AO16: 129 | AP16: 129 | AQ16: 129 | AR16: 129 | AS16: 129 | AT16: 129 | AU16: 129 | AV16: 129 | AW16: 129 | AX16: 129 | AY16: 129 | AZ16: 129 | BA16: 129 | BB16: 105 | BC16: 105 | BD16: 105 | BE16: 105 | BF16: 105 | BG16: 105 | BH16: 105 | BI16: 105 | BJ16: 105 | BK16: 105 | BL16: 105 | BM16: 105 | BN16: 105 | BO16: 105 | BP16: 105 | BQ16: 105 | BR16: 105 | BS16: 105 | BT16: 105 | BU16: 105 | BV16: 105 | BW16: 105 | BX16: =BW16-BY16 -> 105
A17: 13 | B17: GR012 | C17: 12 | D17: Miscellious | E17: Nicoband | F17: Nicoband | G17: 10m x 15cm | H17: EA | I17: =20+750 -> 770 | J17: =SUMIFS('POR Control Log-income'!L:L,'POR Control Log-income'!F:F,본공사입.출고현황!B17) -> 20 | K17: =I17-J17 -> 750 | M17: =SUMIFS('POR Control Log-income'!L:L,'POR Control Log-income'!F:F,본공사입.출고현황!B17) -> 20 | N17: =J17-M17 -> 0 | O17: =M17 -> 20 | P17: =SUMIFS('POR Control Log-out'!L:L,'POR Control Log-out'!D:D,본공사입.출고현황!B17) -> 11 | R17: 0 | S17: =O17-Q17-R17-P17 -> 9 | V17: Nicoband | W17: 10m x 15cm | X17: EA | AC17: 24 | AD17: m | AG17: =BM17-S17 -> 7 | AI17: 20 | AK17: 20 | AL17: 20 | AM17: 20 | AN17: 19 | AO17: 19 | AP17: 19 | AQ17: 19 | AR17: 19 | AS17: 19 | AT17: 19 | AU17: 19 | AV17: 19 | AW17: 19 | AX17: 19 | AY17: 19 | AZ17: 17 | BA17: 17 | BB17: 16 | BC17: 16 | BD17: 16 | BE17: 16 | BF17: 16 | BG17: 16 | BH17: 16 | BI17: 16 | BJ17: 16 | BK17: 16 | BL17: 16 | BM17: 16 | BN17: 16 | BO17: 16 | BP17: 16 | BQ17: 16 | BR17: 16 | BS17: 16 | BT17: 16 | BU17: 16 | BV17: 16 | BW17: 16 | BX17: =BW17-BY17 -> 16
A18: 14 | B18: GR013 | C18: 13 | D18: Ground Conduit | E18: Flexible Conduit 2" | F18: Ground Conduit | G18: 2" | H18: M | I18: 2200 | J18: =SUMIFS('POR Control Log-income'!L:L,'POR Control Log-income'!F:F,본공사입.출고현황!B18) -> 2200 | K18: =I18-J18 -> 0 | M18: =SUMIFS('POR Control Log-income'!L:L,'POR Control Log-income'!F:F,본공사입.출고현황!B18) -> 2200 | N18: =J18-M18 -> 0 | O18: 2200 | P18: =SUMIFS('POR Control Log-out'!L:L,'POR Control Log-out'!D:D,본공사입.출고현황!B18) -> 859 | R18: 121 | S18: =O18-Q18-R18-P18 -> 1220 | V18: Flexible Conduit | W18: 2", 50mm | X18: M | AC18: 632.46 | AG18: =BM18-S18 -> 58 | AI18: 1500 | AK18: 1500 | AL18: 1500 | AM18: 1500 | AN18: 1500 | AO18: 1500 | AP18: 1450 | AQ18: 1320 | AR18: 1320 | AS18: 1320 | AT18: 1320 | AU18: 1320 | AV18: 1320 | AW18: 1320 | AX18: 1278 | AY18: 1278 | AZ18: 1278 | BA18: 1278 | BB18: 1278 | BC18: 1278 | BD18: 1278 | BE18: 1278 | BF18: 1278 | BG18: 1278 | BH18: 1278 | BI18: 1278 | BJ18: 1278 | BK18: 1278 | BL18: 1278 | BM18: 1278 | BN18: 1278 | BO18: 1278 | BP18: 1276 | BQ18: 1276 | BR18: 1276 | BS18: 1247.5 | BT18: 1247.5 | BU18: 1247.5 | BV18: 1247.5 | BW18: 1220 | BX18: =BW18-BY18 -> 1220
A19: 15 | B19: GR014 | C19: 14 | D19: PVC PIPE | E19: PVC Flexible Pipe ф 20 | F19: PVC PIPE | G19: ф20 | H19: M | I19: 140 | J19: =SUMIFS('POR Control Log-income'!L:L,'POR Control Log-income'!F:F,본공사입.출고현황!B19) -> 140 | K19: =I19-J19 -> 0 | M19: =SUMIFS('POR Control Log-income'!L:L,'POR Control Log-income'!F:F,본공사입.출고현황!B19) -> 140 | N19: =J19-M19 -> 0 | O19: =M19 -> 140 | P19: =SUMIFS('POR Control Log-out'!L:L,'POR Control Log-out'!D:D,본공사입.출고현황!B19) -> 0 | R19: 0 | S19: =O19-Q19-R19-P19 -> 140 | V19: PVC Flexible Pipe ф 20 | W19: ф20 | X19: M | AG19: =BM19-S19 -> -140 | AI19: 60 | AK19: 60 | AL19: 60 | AM19: 60 | AN19: 60 | AO19: 60 | AP19: 60 | AQ19: 60 | AR19: 60 | AS19: 60 | AT19: 60 | AU19: 60 | AV19: 60 | AW19: 60 | AX19: 60 | AY19: 60 | AZ19: 60 | BA19: 60 | BB19: 60 | BC19: 60 | BW19: 140 | BX19: =BW19-BY19 -> 140
A20: 16 | B20: GR015 | C20: 15 | D20: Ground | E20: nVent Exothemic Welding Control Unit | F20: CAD WELD GUN | H20: EA | I20: 3 | J20: =SUMIFS('POR Control Log-income'!L:L,'POR Control Log-income'!F:F,본공사입.출고현황!B20) -> 3 | K20: =I20-J20 -> 0 | M20: =SUMIFS('POR Control Log-income'!L:L,'POR Control Log-income'!F:F,본공사입.출고현황!B20) -> 3 | N20: =J20-M20 -> 0 | O20: =M20 -> 3 | P20: =SUMIFS('POR Control Log-out'!L:L,'POR Control Log-out'!D:D,본공사입.출고현황!B20) -> 2 | R20: 0 | S20: =O20-Q20-R20-P20 -> 1 | U20: 1 | V20: Welding Control Unit | X20: EA | AG20: =BM20-S20 -> 0 | AI20: 1 | AK20: 1 | AL20: 1 | AM20: 1 | AN20: 1 | AO20: 1 | AP20: 1 | AQ20: 1 | AR20: 1 | AS20: 1 | AT20: 1 | AU20: 1 | AV20: 1 | AW20: 1 | AX20: 1 | AY20: 1 | AZ20: 1 | BA20: 1 | BB20: 1 | BC20: 1 | BD20: 1 | BE20: 1 | BF20: 1 | BG20: 1 | BH20: 1 | BI20: 1 | BJ20: 1 | BK20: 1 | BL20: 1 | BM20: 1 | BN20: 1 | BO20: 1 | BP20: 1 | BQ20: 1 | BR20: 1 | BS20: 1 | BT20: 1 | BU20: 1 | BV20: 1 | BW20: 1 | BX20: =BW20-BY20 -> 1
A21: 17 | C21: B | E21: Conduit | J21: =SUMIFS('POR Control Log-income'!L:L,'POR Control Log-income'!F:F,본공사입.출고현황!B21) -> 0 | M21: =SUMIFS('POR Control Log-income'!L:L,'POR Control Log-income'!F:F,본공사입.출고현황!B21) -> 0 | N21: =J21-M21 -> 0 | S21: =O21-Q21-R21-P21 -> 0 | AG21: =BM21-S21 -> 0 | AM21: 0 | AN21: 0 | AO21: 0 | AP21: 0 | AQ21: 0 | AR21: 0 | AS21: 0 | AT21: 0 | AU21: 0 | AV21: 0 | AW21: 0 | AX21: 0 | AY21: 0 | AZ21: 0 | BA21: 0 | BB21: 0 | BC21: 0 | BD21: 0 | BE21: 0 | BF21: 0 | BG21: 0 | BH21: 0 | BI21: 0 | BJ21: 0 | BK21: 0 | BL21: 0 | BM21: 0 | BN21: 0 | BO21: 0 | BP21: 0 | BQ21: 0 | BR21: 0 | BS21: 0 | BT21: 0 | BU21: 0 | BV21: 0 | BX21: =BW21-BY21 -> 0
A22: 18 | B22: CO001 | C22: 1 | D22: Conduit | E22: Conduit (Galvanized) Ts-100x4.5 | F22: Conduit (Galvanized) | G22: 114x4.5 | H22: M | I22: 2551 | J22: =SUMIFS('POR Control Log-income'!L:L,'POR Control Log-income'!F:F,본공사입.출고현황!B22) -> 2437 | K22: =I22-J22 -> 114 | M22: =SUMIFS('POR Control Log-income'!L:L,'POR Control Log-income'!F:F,본공사입.출고현황!B22) -> 2437 | N22: =J22-M22 -> 0 | O22: =M22 -> 2437 | P22: =SUMIFS('POR Control Log-out'!L:L,'POR Control Log-out'!D:D,본공사입.출고현황!B22) -> 1438 | Q22: =311+97+189 -> 597 | R22: 270 | S22: =O22-Q22-R22-P22 -> 132 | V22: Conduit (Galvanized) | W22: 4.5" | X22: M | Y22: O | AB22: 3" | AC22: 1331.121 | AD22: =AC22-P23 -> -120.879 | AG22: =BM22-S22 -> 600.6 | AI22: 68 | AK22: 68 | AL22: 68 | AM22: 68 | AN22: 68 | AO22: 68 | AP22: 68 | AQ22: 68 | AR22: 68 | AS22: 68 | AT22: 68 | AU22: 68 | AV22: 68 | AW22: 68 | AX22: 68 | AZ22: 0 | BA22: 0 | BB22: 0 | BC22: 0 | BD22: 830 | BE22: 830 | BF22: 732.6 | BG22: 732.6 | BH22: 732.6 | BI22: 732.6 | BJ22: 732.6 | BK22: 732.6 | BL22: 732.6 | BM22: 732.6 | BN22: 732.6 | BO22: 732.6 | BP22: 732.6 | BQ22: 732.6 | BR22: 732.6 | BS22: 732.6 | BT22: 732.6 | BU22: 732.6 | BV22: 732.6 | BW22: 840 | BX22: =BW22-BY22 -> 840
A23: 19 | B23: CO002 | C23: 2 | D23: Conduit | E23: Conduit (Galvanized) Ts-80x4 | F23: Conduit (Galvanized) | G23: 88x4 | H23: M | I23: 5390 | J23: =SUMIFS('POR Control Log-income'!L:L,'POR Control Log-income'!F:F,본공사입.출고현황!B23) -> 5390 | K23: =I23-J23 -> 0 | M23: =SUMIFS('POR Control Log-income'!L:L,'POR Control Log-income'!F:F,본공사입.출고현황!B23) -> 5390 | N23: =J23-M23 -> 0 | O23: =M23 -> 5390 | P23: =SUMIFS('POR Control Log-out'!L:L,'POR Control Log-out'!D:D,본공사입.출고현황!B23) -> 1452 | Q23: =198+58-120+240+84 -> 460 | R23: 238 | S23: =O23-Q23-R23-P23 -> 3240 | T23: ULD 및 UGD 필요수량 포함 | V23: Conduit (Galvanized) | W23: 3" | X23: M | Y23: O | AB23: 4" | AC23: 5156.088 | AD23: =AC23-P29 -> -0.4 | AG23: =BM23-S23 -> 84 | AI23: 612 | AK23: 612 | AL23: 612 | AM23: 612 | AN23: 612 | AO23: 612 | AP23: 612 | AQ23: 612 | AR23: 612 | AS23: 612 | AT23: 612 | AU23: 612 | AV23: 612 | AW23: 612 | AX23: 612 | AY23: 3618 | AZ23: 3564 | BA23: 3564 | BB23: 3564 | BC23: 3564 | BD23: 3564 | BE23: 3564 | BF23: 3324 | BG23: 3324 | BH23: 3324 | BI23: 3324 | BJ23: 3324 | BK23: 3324 | BL23: 3324 | BM23: 3324 | BN23: 3324 | BO23: 3324 | BP23: 3324 | BQ23: 3324 | BR23: 3324 | BS23: 3324 | BT23: 3324 | BU23: 3324 | BV23: 3324 | BW23: 3324 | BX23: =BW23-BY23 -> 3324
A24: 20 | B24: XX-CO003 | C24: 3 | D24: Conduit | E24: Conduit 159x4.5 | F24: Conduit | G24: 159x6.0 | H24: M | I24: 0 | J24: =SUMIFS('POR Control Log-income'!L:L,'POR Control Log-income'!F:F,본공사입.출고현황!B24) -> 0 | K24: =I24-J24 -> 0 | M24: =SUMIFS('POR Control Log-income'!L:L,'POR Control Log-income'!F:F,본공사입.출고현황!B24) -> 0 | N24: =J24-M24 -> 0 | O24: =M24 -> 0 | P24: =SUMIFS('POR Control Log-out'!L:L,'POR Control Log-out'!D:D,본공사입.출고현황!B24) -> 0 | S24: =O24-Q24-R24-P24 -> 0 | T24: 설계 변경 → 6.5"(168mm) | U24: holding | V24: Conduit | W24: 6" | X24: M | Y24: 삭제 요망 | AB24: 4.5" | AC24: 933.165 | AD24: =AC24-P22 -> -504.835 | AG24: =BM24-S24 -> 0 | AM24: 0 | AN24: 0 | AO24: 0 | AP24: 0 | AQ24: 0 | AR24: 0 | AS24: 0 | AT24: 0 | AU24: 0 | AV24: 0 | AW24: 0 | AX24: 0 | AY24: 0 | AZ24: 0 | BA24: 0 | BB24: 0 | BC24: 0 | BD24: 0 | BE24: 0 | BF24: 0 | BG24: 0 | BH24: 0 | BI24: 0 | BJ24: 0 | BK24: 0 | BL24: 0 | BM24: 0 | BN24: 0 | BO24: 0 | BP24: 0 | BQ24: 0 | BR24: 0 | BS24: 0 | BT24: 0 | BU24: 0 | BV24: 0 | BW24: 0 | BX24: =BW24-BY24 -> 0
A25: 25 | B25: CO003 | C25: 4 | D25: Conduit | E25: Conduit (Galvanized) 168x6 | F25: Conduit (Galvanized) | G25: 168x6 | H25: M | I25: 172 | J25: =SUMIFS('POR Control Log-income'!L:L,'POR Control Log-income'!F:F,본공사입.출고현황!B25) -> 0 | K25: =I25-J25 -> 172 | M25: =SUMIFS('POR Control Log-income'!L:L,'POR Control Log-income'!F:F,본공사입.출고현황!B25) -> 0 | N25: =J25-M25 -> 0 | O25: =M25 -> 0 | P25: =SUMIFS('POR Control Log-out'!L:L,'POR Control Log-out'!D:D,본공사입.출고현황!B25) -> 0 | R25: 0 | S25: =O25-Q25-R25-P25 -> 0 | T25: 설계 추가 | V25: Conduit (Galvanized) | W25: 6.5" | X25: M | Y25: O | AB25: 5.5" | AC25: 0 | AD25: =AC25-P27 -> 0 | AG25: =BM25-S25 -> 0 | AM25: 0 | AN25: 0 | AO25: 0 | AP25: 0 | AQ25: 0 | AR25: 0 | AS25: 0 | AT25: 0 | AU25: 0 | AV25: 0 | AW25: 0 | AX25: 0 | AY25: 0 | AZ25: 0 | BA25: 0 | BB25: 0 | BD25: 0 | BE25: 0 | BF25: 0 | BG25: 0 | BH25: 0 | BI25: 0 | BJ25: 0 | BK25: 0 | BL25: 0 | BM25: 0 | BN25: 0 | BO25: 0 | BP25: 0 | BQ25: 0 | BR25: 0 | BS25: 0 | BT25: 0 | BU25: 0 | BV25: 0 | BW25: 172 | BX25: =BW25-BY25 -> 172
A26: 21 | B26: CO004 | C26: 5 | D26: Conduit | E26: Conduit 159x4.5 | F26: Conduit | G26: 159x4.5 | H26: M | I26: 1400.32 | J26: =SUMIFS('POR Control Log-income'!L:L,'POR Control Log-income'!F:F,본공사입.출고현황!B26) -> 1400.32 | K26: =I26-J26 -> 0 | M26: =SUMIFS('POR Control Log-income'!L:L,'POR Control Log-income'!F:F,본공사입.출고현황!B26) -> 1400.32 | N26: =J26-M26 -> 0 | O26: =M26 -> 1400.32 | P26: =SUMIFS('POR Control Log-out'!L:L,'POR Control Log-out'!D:D,본공사입.출고현황!B26) -> 1176 | R26: 116.32 | S26: =O26-Q26-R26-P26 -> 108 | V26: Conduit | W26: 6" | X26: M | Y26: O | AB26: 6" | AC26: 1175.36 | AD26: =AC26-P26 -> -0.64 | AG26: =BM26-S26 -> 0 | AI26: 190 | AJ26: 162 | AK26: 162 | AL26: 162 | AM26: 162 | AN26: 162 | AO26: 162 | AP26: 162 | AQ26: 162 | AR26: 162 | AS26: 162 | AT26: 162 | AU26: 162 | AV26: 156 | AW26: 156 | AX26: 156 | AY26: 108 | AZ26: 108 | BA26: 108 | BB26: 108 | BC26: 108 | BD26: 108 | BE26: 108 | BF26: 108 | BG26: 108 | BH26: 108 | BI26: 108 | BJ26: 108 | BK26: 108 | BL26: 108 | BM26: 108 | BN26: 108 | BO26: 108 | BP26: 108 | BQ26: 108 | BR26: 108 | BS26: 108 | BT26: 108 | BU26: 108 | BV26: 108 | BW26: 108 | BX26: =BW26-BY26 -> 108
A27: 22 | B27: CO005 | C27: 6 | D27: Conduit | E27: Conduit (Galvanized) 140x5 | F27: Conduit (Galvanized) | G27: 140x5 | H27: M | I27: 530 | J27: =SUMIFS('POR Control Log-income'!L:L,'POR Control Log-income'!F:F,본공사입.출고현황!B27) -> 530 | K27: =I27-J27 -> 0 | M27: =SUMIFS('POR Control Log-income'!L:L,'POR Control Log-income'!F:F,본공사입.출고현황!B27) -> 530 | N27: =J27-M27 -> 0 | O27: =M27 -> 530 | P27: =SUMIFS('POR Control Log-out'!L:L,'POR Control Log-out'!D:D,본공사입.출고현황!B27) -> 0 | Q27: 189 | R27: 0 | S27: =O27-Q27-R27-P27 -> 341 | U27: holding | V27: Conduit (Galvanized) | W27: 5.5" | X27: M | AB27: 6.5" | AC27: 0 | AD27: =AC27-P25 -> 0 | AG27: =BM27-S27 -> 0.16 | AM27: 0 | AN27: 0 | AO27: 0 | AP27: 0 | AQ27: 0 | AR27: 451 | AS27: 451 | AT27: 451 | AU27: 451 | AV27: 451 | AW27: 451 | AX27: 451 | AY27: 451 | AZ27: 451 | BA27: 451 | BB27: 451 | BC27: 451 | BD27: =451+79 -> 530 | BE27: 530 | BF27: 341.16 | BG27: 341.16 | BH27: 341.16 | BI27: 341.16 | BJ27: 341.16 | BK27: 341.16 | BL27: 341.16 | BM27: 341.16 | BN27: 341.16 | BO27: 341.16 | BP27: 341.16 | BQ27: 341.16 | BR27: 341.16 | BS27: 341.16 | BT27: 341.16 | BU27: 341.16 | BV27: 341.16 | BW27: 341 | BX27: =BW27-BY27 -> 341
A28: 23 | B28: XX-CO006 | C28: 7 | D28: Conduit | E28: Conduit 108x5 | F28: Conduit | G28: 108x5 | H28: M | I28: 0 | J28: =SUMIFS('POR Control Log-income'!L:L,'POR Control Log-income'!F:F,본공사입.출고현황!B28) -> 0 | K28: =I28-J28 -> 0 | M28: =SUMIFS('POR Control Log-income'!L:L,'POR Control Log-income'!F:F,본공사입.출고현황!B28) -> 0 | N28: =J28-M28 -> 0 | O28: =M28 -> 0 | P28: =SUMIFS('POR Control Log-out'!L:L,'POR Control Log-out'!D:D,본공사입.출고현황!B28) -> 0 | R28: 0 | S28: =O28-Q28-R28-P28 -> 0 | T28: 설계 삭제(토건 역무) | U28: holding | V28: Conduit | W28: 4" | X28: M | Y28: 삭제 요망 | AG28: =BM28-S28 -> 0 | AM28: 0 | AN28: 0 | AO28: 0 | AP28: 0 | AQ28: 0 | AR28: 0 | AS28: 0 | AT28: 0 | AU28: 0 | AV28: 0 | AW28: 0 | AX28: 0 | AY28: 0 | AZ28: 0 | BA28: 0 | BB28: 0 | BC28: 0 | BD28: 0 | BE28: 0 | BF28: 0 | BG28: 0 | BH28: 0 | BI28: 0 | BJ28: 0 | BK28: 0 | BL28: 0 | BM28: 0 | BN28: 0 | BO28: 0 | BP28: 0 | BQ28: 0 | BR28: 0 | BS28: 0 | BT28: 0 | BU28: 0 | BV28: 0 | BW28: 0 | BX28: =BW28-BY28 -> 0
A29: 24 | B29: CO007 | C29: 8 | D29: Conduit | E29: Conduit 108x4.0 | F29: Conduit | G29: 108x4 | H29: M | I29: =5956+84 -> 6040 | J29: =SUMIFS('POR Control Log-income'!L:L,'POR Control Log-income'!F:F,본공사입.출고현황!B29) -> 5956 | K29: =I29-J29 -> 84 | L29: 66 | M29: =SUMIFS('POR Control Log-income'!L:L,'POR Control Log-income'!F:F,본공사입.출고현황!B29) -> 5956 | N29: =J29-M29 -> 0 | O29: =M29 -> 5956 | P29: =SUMIFS('POR Control Log-out'!L:L,'POR Control Log-out'!D:D,본공사입.출고현황!B29) -> 5156.488 | Q29: 113 | R29: =555.512 -> 555.512 | S29: =O29-Q29-R29-P29 -> 131 | T29: (Scrap 555.5)-(발전기 굴뚝 : 86M) | V29: Conduit | W29: 4" | X29: M | Y29: O | AG29: =BM29-S29 -> -66 | AI29: 937.5 | AJ29: 841 | AK29: =670-30 -> 640 | AL29: 640 | AM29: 640 | AN29: 640 | AO29: 467 | AP29: 467 | AQ29: 467 | AR29: 447 | AS29: 314 | AT29: 314 | AU29: 307.5 | AV29: 305.5 | AW29: 295.5 | AX29: 295.5 | AY29: 235.17 | AZ29: 235.17 | BA29: 122.9 | BB29: 65 | BC29: 65 | BD29: 65 | BE29: 65 | BF29: 65 | BG29: 65 | BH29: 65 | BI29: 65 | BJ29: 65 | BK29: 65 | BL29: 65 | BM29: 65 | BN29: 65 | BO29: 65 | BP29: 65 | BQ29: 65 | BR29: 65 | BS29: 65 | BT29: 65 | BU29: 65 | BV29: 65 | BW29: 131 | BX29: =BW29-BY29 -> 131
A30: 25 | B30: CO008.1 | C30: 9 | D30: Conduit | E30: Conduit (Galvanized) 60.3x3.91 | F30: Conduit (Galvanized) | G30: 60.3x3.91 | H30: M | I30: 18 | J30: =SUMIFS('POR Control Log-income'!L:L,'POR Control Log-income'!F:F,본공사입.출고현황!B30) -> 18 | K30: =I30-J30 -> 0 | M30: =SUMIFS('POR Control Log-income'!L:L,'POR Control Log-income'!F:F,본공사입.출고현황!B30) -> 18 | N30: =J30-M30 -> 0 | O30: =M30 -> 18 | P30: =SUMIFS('POR Control Log-out'!L:L,'POR Control Log-out'!D:D,본공사입.출고현황!B30) -> 18 | Q30: 0 | R30: 0 | S30: =O30-Q30-R30-P30 -> 0 | T30: 추가 | V30: Conduit (Galvanized) | W30: 2" | X30: M | AG30: =BM30-S30 -> 0 | AM30: 0 | AN30: 0 | AO30: 0 | AP30: 0 | AQ30: 0 | AR30: 0 | AS30: 0 | AT30: 0 | AU30: 0 | AV30: 0 | AW30: 0 | AX30: 0 | AY30: 0 | AZ30: 0 | BA30: 0 | BB30: 0 | BD30: 0 | BE30: 0 | BF30: 0 | BG30: 0 | BH30: 0 | BI30: 0 | BJ30: 0 | BK30: 0 | BL30: 0 | BM30: 0 | BN30: 0 | BO30: 0 | BP30: 0 | BQ30: 0 | BR30: 0 | BS30: 0 | BT30: 0 | BU30: 0 | BV30: 0 | BW30: 0 | BX30: =BW30-BY30 -> 0
A31: 26 | B31: CO009 | C31: 10 | D31: Conduit Fitting | E31: Conduit Coupling 168x4 | F31: Conduit Coupling | G31: 168x4 | H31: M | I31: 44 | J31: =SUMIFS('POR Control Log-income'!L:L,'POR Control Log-income'!F:F,본공사입.출고현황!B31) -> 44 | K31: =I31-J31 -> 0 | M31: =SUMIFS('POR Control Log-income'!L:L,'POR Control Log-income'!F:F,본공사입.출고현황!B31) -> 44 | N31: =J31-M31 -> 0 | O31: =M31 -> 44 | P31: =SUMIFS('POR Control Log-out'!L:L,'POR Control Log-out'!D:D,본공사입.출고현황!B31) -> 1.3 | R31: 0 | S31: =O31-Q31-R31-P31 -> 42.7 | T31: =S31/0.15 -> 284.66667 | U31: =S31/293 -> 0.14573379 | V31: Coupling | W31: 6" | X31: EA | Y31: O | AG31: =BM31-S31 -> 0 | AK31: 44 | AL31: 44 | AM31: 44 | AN31: 44 | AO31: 44 | AP31: 44 | AQ31: 44 | AR31: 44 | AS31: 44 | AT31: 44 | AU31: 44 | AV31: 43 | AW31: 42.7 | AX31: 42.7 | AY31: 42.7 | AZ31: 42.7 | BA31: 42.7 | BB31: 42.7 | BC31: 42.7 | BD31: 42.7 | BE31: 42.7 | BF31: 42.7 | BG31: 42.7 | BH31: 42.7 | BI31: 42.7 | BJ31: 42.7 | BK31: 42.7 | BL31: 42.7 | BM31: 42.7 | BN31: 42.7 | BO31: 42.7 | BP31: 42.7 | BQ31: 42.7 | BR31: 42.7 | BS31: 42.7 | BT31: 42.7 | BU31: 42.7 | BV31: 42.7 | BW31: 42.7 | BX31: =BW31-BY31 -> 42.7
A32: 27 | B32: CO010 | C32: 11 | D32: Conduit Fitting | E32: Conduit Coupling 168x4 | F32: Conduit Coupling | G32: 168x4 | H32: EA | I32: 200 | J32: =SUMIFS('POR Control Log-income'!L:L,'POR Control Log-income'!F:F,본공사입.출고현황!B32) -> 200 | K32: =I32-J32 -> 0 | M32: =SUMIFS('POR Control Log-income'!L:L,'POR Control Log-income'!F:F,본공사입.출고현황!B32) -> 200 | N32: =J32-M32 -> 0 | O32: =M32 -> 200 | P32: =SUMIFS('POR Control Log-out'!L:L,'POR Control Log-out'!D:D,본공사입.출고현황!B32) -> 188 | Q32: 0 | R32: 0 | S32: =O32-Q32-R32-P32 -> 12 | V32: Coupling | W32: 6" | X32: EA | Y32: O | AG32: =BM32-S32 -> 0 | AK32: 26 | AL32: 18 | AM32: 18 | AN32: 18 | AO32: 18 | AP32: 18 | AQ32: 18 | AR32: 18 | AS32: 18 | AT32: 12 | AU32: 12 | AV32: 12 | AW32: 12 | AX32: 12 | AY32: 12 | AZ32: 12 | BA32: 12 | BB32: 12 | BC32: 12 | BD32: 12 | BE32: 12 | BF32: 12 | BG32: 12 | BH32: 12 | BI32: 12 | BJ32: 12 | BK32: 12 | BL32: 12 | BM32: 12 | BN32: 12 | BO32: 12 | BP32: 12 | BQ32: 12 | BR32: 12 | BS32: 12 | BT32: 12 | BU32: 12 | BV32: 12 | BW32: 12 | BX32: =BW32-BY32 -> 12
A33: 28 | B33: CO011 | C33: 12 | D33: Conduit Fitting | E33: Conduit Coupling 125-Ts | F33: Conduit Coupling | G33: Ts-125x5 | H33: EA | I33: =60+60 -> 120 | J33: =SUMIFS('POR Control Log-income'!L:L,'POR Control Log-income'!F:F,본공사입.출고현황!B33) -> 60 | K33: =I33-J33 -> 60 | M33: =SUMIFS('POR Control Log-income'!L:L,'POR Control Log-income'!F:F,본공사입.출고현황!B33) -> 60 | N33: =J33-M33 -> 0 | O33: =M33 -> 60 | P33: =SUMIFS('POR Control Log-out'!L:L,'POR Control Log-out'!D:D,본공사입.출고현황!B33) -> 0 | Q33: 14 | R33: 0 | S33: =O33-Q33-R33-P33 -> 46 | U33: holding | V33: Coupling (Galvanized) | W33: 5.5" | X33: EA | AG33: =BM33-S33 -> 14 | AM33: 0 | AN33: 0 | AO33: 0 | AP33: 0 | AQ33: 0 | AR33: 0 | AS33: 0 | AT33: 0 | AU33: 0 | AV33: 0 | AW33: 0 | AX33: 0 | AY33: 0 | AZ33: 0 | BA33: 0 | BB33: 0 | BD33: 60 | BE33: 60 | BF33: 60 | BG33: 60 | BH33: 60 | BI33: 60 | BJ33: 60 | BK33: 60 | BL33: 60 | BM33: 60 | BN33: 60 | BO33: 60 | BP33: 60 | BQ33: 60 | BR33: 60 | BS33: 60 | BT33: 60 | BU33: 60 | BV33: 60 | BW33: 60 | BX33: =BW33-BY33 -> 60
A34: 29 | B34: CO012 | C34: 13 | D34: Conduit Fitting | E34: Conduit Coupling 121x5 | F34: Conduit Coupling | G34: 121x5 | H34: M | I34: 104 | J34: =SUMIFS('POR Control Log-income'!L:L,'POR Control Log-income'!F:F,본공사입.출고현황!B34) -> 104 | K34: =I34-J34 -> 0 | M34: =SUMIFS('POR Control Log-income'!L:L,'POR Control Log-income'!F:F,본공사입.출고현황!B34) -> 104 | N34: =J34-M34 -> 0 | O34: =M34 -> 104 | P34: =SUMIFS('POR Control Log-out'!L:L,'POR Control Log-out'!D:D,본공사입.출고현황!B34) -> 48 | Q34: 1.5 | R34: 0 | S34: =O34-Q34-R34-P34 -> 54.5 | T34: =S34/0.15 -> 363.33333 | U34: =S34/613 -> 0.088907015 | V34: Coupling | W34: 4" | X34: EA | Y34: O | AG34: =BM34-S34 -> 0 | AI34: 72.5 | AJ34: 72.5 | AK34: 72.5 | AL34: 71.5 | AM34: =71.5-1.5 -> 70 | AN34: 71.5 | AO34: 71.5 | AP34: 71.5 | AQ34: 71.5 | AR34: 68.5 | AS34: 68.5 | AT34: 68.5 | AU34: 56.5 | AV34: 54.5 | AW34: 54.5 | AX34: 54.5 | AY34: 54.5 | AZ34: 54.5 | BA34: 54.5 | BB34: 54.5 | BC34: 54.5 | BD34: 54.5 | BE34: 54.5 | BF34: 54.5 | BG34: 54.5 | BH34: 54.5 | BI34: 54.5 | BJ34: 54.5 | BK34: 54.5 | BL34: 54.5 | BM34: 54.5 | BN34: 54.5 | BO34: 54.5 | BP34: 54.5 | BQ34: 54.5 | BR34: 54.5 | BS34: 54.5 | BT34: 54.5 | BU34: 54.5 | BV34: 54.5 | BW34: 54.5 | BX34: =BW34-BY34 -> 54.5
A35: 30 | B35: CO013 | C35: 14 | D35: Conduit Fitting | E35: Conduit Coupling 121x5 | F35: Conduit Coupling | G35: 121x5 | H35: EA | I35: 456 | J35: =SUMIFS('POR Control Log-income'!L:L,'POR Control Log-income'!F:F,본공사입.출고현황!B35) -> 456 | K35: =I35-J35 -> 0 | M35: =SUMIFS('POR Control Log-income'!L:L,'POR Control Log-income'!F:F,본공사입.출고현황!B35) -> 456 | N35: =J35-M35 -> 0 | O35: =M35 -> 456 | P35: =SUMIFS('POR Control Log-out'!L:L,'POR Control Log-out'!D:D,본공사입.출고현황!B35) -> 423 | Q35: 33 | R35: 0 | S35: =O35-Q35-R35-P35 -> 0 | V35: Coupling | W35: 4" | X35: EA | Y35: O | AG35: =BM35-S35 -> 0 | AM35: 0 | AN35: 0 | AO35: 0 | AP35: 0 | AQ35: 0 | AR35: 0 | AS35: 0 | AT35: 0 | AU35: 0 | AV35: 0 | AW35: 0 | AX35: 0 | AY35: 0 | AZ35: 0 | BA35: 0 | BB35: 0 | BC35: 0 | BD35: 0 | BE35: 0 | BF35: 0 | BG35: 0 | BH35: 0 | BI35: 0 | BJ35: 0 | BK35: 0 | BL35: 0 | BM35: 0 | BN35: 0 | BO35: 0 | BP35: 0 | BQ35: 0 | BR35: 0 | BS35: 0 | BT35: 0 | BU35: 0 | BV35: 0 | BW35: 0 | BX35: =BW35-BY35 -> 0
A36: 31 | B36: CO014 | C36: 15 | D36: Conduit Fitting | E36: Conduit Coupling 100-Ts | F36: Conduit Coupling | G36: 100-Ts | H36: EA | I36: 280 | J36: =SUMIFS('POR Control Log-income'!L:L,'POR Control Log-income'!F:F,본공사입.출고현황!B36) -> 280 | K36: =I36-J36 -> 0 | M36: =SUMIFS('POR Control Log-income'!L:L,'POR Control Log-income'!F:F,본공사입.출고현황!B36) -> 280 | N36: =J36-M36 -> 0 | O36: =M36 -> 280 | P36: =SUMIFS('POR Control Log-out'!L:L,'POR Control Log-out'!D:D,본공사입.출고현황!B36) -> 175 | R36: 0 | S36: =O36-Q36-R36-P36 -> 105 | V36: Coupling (Galvanized) | W36: 4.5" | X36: EA | Y36: O | AG36: =BM36-S36 -> 20 | AI36: 7 | AJ36: 7 | AK36: 7 | AL36: 7 | AM36: 42 | AO36: 0 | AP36: 0 | AQ36: 0 | AR36: 0 | AS36: 0 | AT36: 0 | AU36: 0 | AV36: 0 | AW36: 0 | AX36: 0 | AY36: 0 | AZ36: 0 | BA36: 0 | BB36: 0 | BD36: 125 | BE36: 125 | BF36: 125 | BG36: 125 | BH36: 125 | BI36: 125 | BJ36: 125 | BK36: 125 | BL36: 125 | BM36: 125 | BN36: 125 | BO36: 125 | BP36: 125 | BQ36: 125 | BR36: 125 | BS36: 125 | BT36: 125 | BU36: 125 | BV36: 125 | BW36: 125 | BX36: =BW36-BY36 -> 125
A37: 32 | B37: CO015 | C37: 16 | D37: Conduit Fitting | E37: Conduit Coupling 80-Ts | F37: Conduit Coupling | G37: 80-Ts | H37: EA | I37: 440 | J37: =SUMIFS('POR Control Log-income'!L:L,'POR Control Log-income'!F:F,본공사입.출고현황!B37) -> 440 | K37: =I37-J37 -> 0 | M37: =SUMIFS('POR Control Log-income'!L:L,'POR Control Log-income'!F:F,본공사입.출고현황!B37) -> 440 | N37: =J37-M37 -> 0 | O37: =M37 -> 440 | P37: =SUMIFS('POR Control Log-out'!L:L,'POR Control Log-out'!D:D,본공사입.출고현황!B37) -> 368 | R37: 0 | S37: =O37-Q37-R37-P37 -> 72 | V37: Coupling (Galvanized) | W37: 3" | X37: EA | Y37: O | AG37: =BM37-S37 -> -11 | AI37: 188 | AJ37: 188 | AK37: 188 | AL37: 188 | AM37: 188 | AN37: 188 | AO37: 188 | AP37: 188 | AQ37: 188 | AR37: 188 | AS37: 60 | AT37: 55 | AU37: 55 | AV37: 55 | AW37: 55 | AX37: 55 | AY37: 55 | AZ37: 55 | BA37: 55 | BB37: 55 | BC37: 53 | BD37: 30 | BE37: 30 | BF37: 30 | BG37: 30 | BH37: 61 | BI37: 61 | BJ37: 61 | BK37: 61 | BL37: 61 | BM37: 61 | BN37: 61 | BO37: 61 | BP37: 61 | BQ37: 61 | BR37: 61 | BS37: 61 | BT37: 61 | BU37: 61 | BV37: 61 | BW37: 299 | BX37: =BW37-BY37 -> 299
B38: CO015.1 | C38: 17 | D38: Conduit Fitting | E38: Conduit Coupling | F38: Conduit Coupling | G38: 50-11 NPT | H38: EA | I38: 9 | J38: =SUMIFS('POR Control Log-income'!L:L,'POR Control Log-income'!F:F,본공사입.출고현황!B38) -> 9 | K38: =I38-J38 -> 0 | M38: =SUMIFS('POR Control Log-income'!L:L,'POR Control Log-income'!F:F,본공사입.출고현황!B38) -> 9 | N38: =J38-M38 -> 0 | O38: =M38 -> 9 | P38: =SUMIFS('POR Control Log-out'!L:L,'POR Control Log-out'!D:D,본공사입.출고현황!B38) -> 9 | Q38: 0 | S38: =O38-Q38-R38-P38 -> 0 | T38: 추가 | V38: Coupling (Galvanized) | W38: 2" | X38: EA
A39: 33 | B39: CO016 | C39: 18 | D39: Sup't | E39: Angle 50x50x5 | F39: Angle | G39: 50*50*5 | H39: M | I39: 3584 | J39: =SUMIFS('POR Control Log-income'!L:L,'POR Control Log-income'!F:F,본공사입.출고현황!B39) -> 3584 | K39: =I39-J39 -> 0 | M39: =SUMIFS('POR Control Log-income'!L:L,'POR Control Log-income'!F:F,본공사입.출고현황!B39) -> 3584 | N39: =J39-M39 -> 0 | O39: =M39 -> 3584 | P39: =SUMIFS('POR Control Log-out'!L:L,'POR Control Log-out'!D:D,본공사입.출고현황!B39) -> 2726 | Q39: 459.1 | R39: =323.9+3 -> 326.9 | S39: =O39-Q39-R39-P39 -> 72 | T39: ULD 및 UGD 필요수량 포함 | V39: Angle | W39: 50*50*5 | X39: M | Y39: O | AG39: =BM39-S39 -> 0 | AI39: 858 | AJ39: 858 | AK39: 840 | AL39: 780 | AM39: 660 | AN39: 636 | AO39: 624 | AP39: 540 | AQ39: 516 | AR39: 396 | AS39: 396 | AT39: 348 | AU39: 264 | AV39: 252 | AW39: 204 | AX39: 204 | AY39: 204 | AZ39: 204 | BA39: 204 | BB39: 204 | BC39: 168 | BD39: 72 | BE39: 72 | BF39: 72 | BG39: 72 | BH39: 72 | BI39: 72 | BJ39: 72 | BK39: 72 | BL39: 72 | BM39: 72 | BN39: 72 | BO39: 72 | BP39: 72 | BQ39: 72 | BR39: 72 | BS39: 72 | BT39: 72 | BU39: 72 | BV39: 72 | BW39: 872 | BX39: =BW39-BY39 -> 872
A40: 34 | B40: CO017 | C40: 19 | D40: Sup't | E40: Angle 70x70x7 | F40: Angle | G40: 70*70*7 | H40: M | I40: 732 | J40: =SUMIFS('POR Control Log-income'!L:L,'POR Control Log-income'!F:F,본공사입.출고현황!B40) -> 732 | K40: =I40-J40 -> 0 | M40: =SUMIFS('POR Control Log-income'!L:L,'POR Control Log-income'!F:F,본공사입.출고현황!B40) -> 732 | N40: =J40-M40 -> 0 | O40: =M40 -> 732 | P40: =SUMIFS('POR Control Log-out'!L:L,'POR Control Log-out'!D:D,본공사입.출고현황!B40) -> 414.4 | R40: 29.6 | S40: =O40-Q40-R40-P40 -> 288 | V40: Angle | W40: 70*70*7 | X40: M | Y40: O | AG40: =BM40-S40 -> 0 | AI40: 432 | AJ40: 432 | AK40: 336 | AL40: 336 | AM40: 336 | AN40: 336 | AO40: 324 | AP40: 324 | AQ40: 324 | AR40: 324 | AS40: 324 | AT40: 324 | AU40: 324 | AV40: 324 | AW40: 324 | AX40: 318 | AY40: 318 | AZ40: 318 | BA40: 318 | BB40: 288 | BC40: 288 | BD40: 288 | BE40: 288 | BF40: 288 | BG40: 288 | BH40: 288 | BI40: 288 | BJ40: 288 | BK40: 288 | BL40: 288 | BM40: 288 | BN40: 288 | BO40: 288 | BP40: 288 | BQ40: 288 | BR40: 288 | BS40: 288 | BT40: 288 | BU40: 288 | BV40: 288 | BW40: 288 | BX40: =BW40-BY40 -> 288
...

Sheet POR Control Log-income
B1: POR CONTROL LOG - Income
B2: 【Project : El-Dabaa Nuclear Power Plant (ENPP) #1 to 4】 | J2: from Doosan to Daesun
B3: No | C3: RSI No | D3: POR | E3: Date | F3: Material No. | G3: Sortation | H3: Items / Services | I3: Applicable Code & Standards | J3: Size | K3: Unit | L3: Q'TY | M3: Remarks
F5: GR001 | G5: =IFERROR(VLOOKUP($F5,본공사입.출고현황!$B:$H,G$182,0),0) -> Ground | H5: =IFERROR(VLOOKUP($F5,본공사입.출고현황!$B:$H,H$182,0),0) -> Ground Cable 78SQ | I5: =IFERROR(VLOOKUP($F5,본공사입.출고현황!$B:$H,I$182,0),0) -> Ground Cable | J5: =IFERROR(VLOOKUP($F5,본공사입.출고현황!$B:$H,J$182,0),0) -> 78SQ | K5: =IFERROR(VLOOKUP($F5,본공사입.출고현황!$B:$H,K$182,0),0) -> M | L5: 6200 | M5: 이전RSI 화인후 수정
F6: GR002 | G6: =IFERROR(VLOOKUP($F6,본공사입.출고현황!$B:$H,G$182,0),0) -> Ground | H6: =IFERROR(VLOOKUP($F6,본공사입.출고현황!$B:$H,H$182,0),0) -> Ground Cable 70SQ | I6: =IFERROR(VLOOKUP($F6,본공사입.출고현황!$B:$H,I$182,0),0) -> Ground Cable | J6: =IFERROR(VLOOKUP($F6,본공사입.출고현황!$B:$H,J$182,0),0) -> 70SQ | K6: =IFERROR(VLOOKUP($F6,본공사입.출고현황!$B:$H,K$182,0),0) -> M | L6: 0 | M6: 이전RSI 화인후 수정
F7: GR003 | G7: =IFERROR(VLOOKUP($F7,본공사입.출고현황!$B:$H,G$182,0),0) -> Ground Fitting | H7: =IFERROR(VLOOKUP($F7,본공사입.출고현황!$B:$H,H$182,0),0) -> Ground TERMINAL LUG 70mm2 | I7: =IFERROR(VLOOKUP($F7,본공사입.출고현황!$B:$H,I$182,0),0) -> Terminal Lug | J7: =IFERROR(VLOOKUP($F7,본공사입.출고현황!$B:$H,J$182,0),0) -> 70mm2 | K7: =IFERROR(VLOOKUP($F7,본공사입.출고현황!$B:$H,K$182,0),0) -> EA | L7: 0 | M7: 이전RSI 화인후 수정
F8: GR004 | G8: =IFERROR(VLOOKUP($F8,본공사입.출고현황!$B:$H,G$182,0),0) -> Ground | H8: =IFERROR(VLOOKUP($F8,본공사입.출고현황!$B:$H,H$182,0),0) -> Cadweld Powder #90 | I8: =IFERROR(VLOOKUP($F8,본공사입.출고현황!$B:$H,I$182,0),0) -> Cadweld Powder | J8: =IFERROR(VLOOKUP($F8,본공사입.출고현황!$B:$H,J$182,0),0) -> #90 | K8: =IFERROR(VLOOKUP($F8,본공사입.출고현황!$B:$H,K$182,0),0) -> EA | L8: 0 | M8: 이전RSI 화인후 수정
F9: GR005 | G9: =IFERROR(VLOOKUP($F9,본공사입.출고현황!$B:$H,G$182,0),0) -> Ground | H9: =IFERROR(VLOOKUP($F9,본공사입.출고현황!$B:$H,H$182,0),0) -> Cadweld Powder #115 | I9: =IFERROR(VLOOKUP($F9,본공사입.출고현황!$B:$H,I$182,0),0) -> Cadweld Powder | J9: =IFERROR(VLOOKUP($F9,본공사입.출고현황!$B:$H,J$182,0),0) -> #115 | K9: =IFERROR(VLOOKUP($F9,본공사입.출고현황!$B:$H,K$182,0),0) -> EA | L9: 0 | M9: 이전RSI 화인후 수정
F10: GR006 | G10: =IFERROR(VLOOKUP($F10,본공사입.출고현황!$B:$H,G$182,0),0) -> Ground | H10: =IFERROR(VLOOKUP($F10,본공사입.출고현황!$B:$H,H$182,0),0) -> Cadweld Powder #150 | I10: =IFERROR(VLOOKUP($F10,본공사입.출고현황!$B:$H,I$182,0),0) -> Cadweld Powder | J10: =IFERROR(VLOOKUP($F10,본공사입.출고현황!$B:$H,J$182,0),0) -> #150 | K10: =IFERROR(VLOOKUP($F10,본공사입.출고현황!$B:$H,K$182,0),0) -> EA | L10: 0 | M10: 이전RSI 화인후 수정
F11: GR007 | G11: =IFERROR(VLOOKUP($F11,본공사입.출고현황!$B:$H,G$182,0),0) -> Ground | H11: =IFERROR(VLOOKUP($F11,본공사입.출고현황!$B:$H,H$182,0),0) -> Cadweld Powder #200 | I11: =IFERROR(VLOOKUP($F11,본공사입.출고현황!$B:$H,I$182,0),0) -> Cadweld Powder | J11: =IFERROR(VLOOKUP($F11,본공사입.출고현황!$B:$H,J$182,0),0) -> #200 | K11: =IFERROR(VLOOKUP($F11,본공사입.출고현황!$B:$H,K$182,0),0) -> EA | L11: 232 | M11: 이전RSI 화인후 수정
F12: GR008 | G12: =IFERROR(VLOOKUP($F12,본공사입.출고현황!$B:$H,G$182,0),0) -> Ground | H12: =IFERROR(VLOOKUP($F12,본공사입.출고현황!$B:$H,H$182,0),0) -> Cadweld XBQ-Y4Y4 | I12: =IFERROR(VLOOKUP($F12,본공사입.출고현황!$B:$H,I$182,0),0) -> Welding Mold | J12: =IFERROR(VLOOKUP($F12,본공사입.출고현황!$B:$H,J$182,0),0) -> Cross (+) | K12: =IFERROR(VLOOKUP($F12,본공사입.출고현황!$B:$H,K$182,0),0) -> EA | L12: 0 | M12: 이전RSI 화인후 수정
F13: GR009 | G13: =IFERROR(VLOOKUP($F13,본공사입.출고현황!$B:$H,G$182,0),0) -> Ground | H13: =IFERROR(VLOOKUP($F13,본공사입.출고현황!$B:$H,H$182,0),0) -> Cadweld PGC-Y4Y4 | I13: =IFERROR(VLOOKUP($F13,본공사입.출고현황!$B:$H,I$182,0),0) -> Welding Mold | J13: =IFERROR(VLOOKUP($F13,본공사입.출고현황!$B:$H,J$182,0),0) -> Parallel (=) | K13: =IFERROR(VLOOKUP($F13,본공사입.출고현황!$B:$H,K$182,0),0) -> EA | L13: 0 | M13: 이전RSI 화인후 수정
F14: GR010 | G14: =IFERROR(VLOOKUP($F14,본공사입.출고현황!$B:$H,G$182,0),0) -> Ground | H14: =IFERROR(VLOOKUP($F14,본공사입.출고현황!$B:$H,H$182,0),0) -> Cadweld TAC-Y4Y4 | I14: =IFERROR(VLOOKUP($F14,본공사입.출고현황!$B:$H,I$182,0),0) -> Welding Mold | J14: =IFERROR(VLOOKUP($F14,본공사입.출고현황!$B:$H,J$182,0),0) -> Cross (T) | K14: =IFERROR(VLOOKUP($F14,본공사입.출고현황!$B:$H,K$182,0),0) -> EA | L14: 0 | M14: 이전RSI 화인후 수정
F15: GR011 | G15: =IFERROR(VLOOKUP($F15,본공사입.출고현황!$B:$H,G$182,0),0) -> Ground | H15: =IFERROR(VLOOKUP($F15,본공사입.출고현황!$B:$H,H$182,0),0) -> Zinc Spray | I15: =IFERROR(VLOOKUP($F15,본공사입.출고현황!$B:$H,I$182,0),0) -> Zinc Spray | J15: =IFERROR(VLOOKUP($F15,본공사입.출고현황!$B:$H,J$182,0),0) -> 0 | K15: =IFERROR(VLOOKUP($F15,본공사입.출고현황!$B:$H,K$182,0),0) -> EA | L15: -30 | M15: 이전RSI 화인후 수정
F16: GR012 | G16: =IFERROR(VLOOKUP($F16,본공사입.출고현황!$B:$H,G$182,0),0) -> Miscellious | H16: =IFERROR(VLOOKUP($F16,본공사입.출고현황!$B:$H,H$182,0),0) -> Nicoband | I16: =IFERROR(VLOOKUP($F16,본공사입.출고현황!$B:$H,I$182,0),0) -> Nicoband | J16: =IFERROR(VLOOKUP($F16,본공사입.출고현황!$B:$H,J$182,0),0) -> 10m x 15cm | K16: =IFERROR(VLOOKUP($F16,본공사입.출고현황!$B:$H,K$182,0),0) -> EA | L16: 0 | M16: 이전RSI 화인후 수정
... F36: CO020 | G36: =IFERROR(VLOOKUP($F36,본공사입.출고현황!$B:$H,G$182,0),0) -> Paint | H36: =IFERROR(VLOOKUP($F36,본공사입.출고현황!$B:$H,H$182,0),0) -> JOTUN Pipe Top-coated Paint | I36: =IFERROR(VLOOKUP($F36,본공사입.출고현황!$B:$H,I$182,0),0) -> Paint | J36: =IFERROR(VLOOKUP($F36,본공사입.출고현황!$B:$H,J$182,0),0) -> 20L | K36: =IFERROR(VLOOKUP($F36,본공사입.출고현황!$B:$H,K$182,0),0) -> CAN | L36: 0 | M36: 이전RSI 화인후 수정
F37: CG001 | G37: =IFERROR(VLOOKUP($F37,본공사입.출고현황!$B:$H,G$182,0),0) -> Steel round bar | H37: Round wire 10Ø | I37: =IFERROR(VLOOKUP($F37,본공사입.출고현황!$B:$H,I$182,0),0) -> CCGG | J37: =IFERROR(VLOOKUP($F37,본공사입.출고현황!$B:$H,J$182,0),0) -> ф10, 1ton=1,620.7m | K37: =IFERROR(VLOOKUP($F37,본공사입.출고현황!$B:$H,K$182,0),0) -> M | L37: 4755.6 | M37: 이전RSI 화인후 수정 | P37: 12893.6 | Q37: =L37-P37 -> -8138
F38: CG002 | G38: =IFERROR(VLOOKUP($F38,본공사입.출고현황!$B:$H,G$182,0),0) -> Angle | H38: Angle 100x100x10 | I38: =IFERROR(VLOOKUP($F38,본공사입.출고현황!$B:$H,I$182,0),0) -> CCGG | J38: =IFERROR(VLOOKUP($F38,본공사입.출고현황!$B:$H,J$182,0),0) -> 100x100x10 (12m) | K38: =IFERROR(VLOOKUP($F38,본공사입.출고현황!$B:$H,K$182,0),0) -> M | M38: 이전RSI 화인후 수정
A39: 1 | B39: 1 | C39: 수기 | E39: 45340 | F39: CO007 | G39: =IFERROR(VLOOKUP($F39,본공사입.출고현황!$B:$H,G$182,0),0) -> Conduit | H39: =IFERROR(VLOOKUP($F39,본공사입.출고현황!$B:$H,H$182,0),0) -> Conduit 108x4.0 | I39: =IFERROR(VLOOKUP($F39,본공사입.출고현황!$B:$H,I$182,0),0) -> Conduit | J39: =IFERROR(VLOOKUP($F39,본공사입.출고현황!$B:$H,J$182,0),0) -> 108x4 | K39: =IFERROR(VLOOKUP($F39,본공사입.출고현황!$B:$H,K$182,0),0) -> M | L39: 2635.22
A40: 2 | B40: 2 | C40: 수기 | E40: 45340 | F40: CO004 | G40: =IFERROR(VLOOKUP($F40,본공사입.출고현황!$B:$H,G$182,0),0) -> Conduit | H40: =IFERROR(VLOOKUP($F40,본공사입.출고현황!$B:$H,H$182,0),0) -> Conduit 159x4.5 | I40: =IFERROR(VLOOKUP($F40,본공사입.출고현황!$B:$H,I$182,0),0) -> Conduit | J40: =IFERROR(VLOOKUP($F40,본공사입.출고현황!$B:$H,J$182,0),0) -> 159x4.5 | K40: =IFERROR(VLOOKUP($F40,본공사입.출고현황!$B:$H,K$182,0),0) -> M | L40: 596.31
A41: 3 | B41: 3 | C41: 수기 | E41: 45340 | F41: CO012 | G41: =IFERROR(VLOOKUP($F41,본공사입.출고현황!$B:$H,G$182,0),0) -> Conduit Fitting | H41: =IFERROR(VLOOKUP($F41,본공사입.출고현황!$B:$H,H$182,0),0) -> Conduit Coupling 121x5 | I41: =IFERROR(VLOOKUP($F41,본공사입.출고현황!$B:$H,I$182,0),0) -> Conduit Coupling | J41: =IFERROR(VLOOKUP($F41,본공사입.출고현황!$B:$H,J$182,0),0) -> 121x5 | K41: =IFERROR(VLOOKUP($F41,본공사입.출고현황!$B:$H,K$182,0),0) -> M | L41: 17.12
A42: 4 | B42: 4 | C42: 수기 | E42: 45340 | F42: CO009 | G42: =IFERROR(VLOOKUP($F42,본공사입.출고현황!$B:$H,G$182,0),0) -> Conduit Fitting | H42: =IFERROR(VLOOKUP($F42,본공사입.출고현황!$B:$H,H$182,0),0) -> Conduit Coupling 168x4 | I42: =IFERROR(VLOOKUP($F42,본공사입.출고현황!$B:$H,I$182,0),0) -> Conduit Coupling | J42: =IFERROR(VLOOKUP($F42,본공사입.출고현황!$B:$H,J$182,0),0) -> 168x4 | K42: =IFERROR(VLOOKUP($F42,본공사입.출고현황!$B:$H,K$182,0),0) -> M | L42: 20
A43: 5 | B43: 5 | C43: 수기 | E43: 45340 | F43: CO016 | G43: =IFERROR(VLOOKUP($F43,본공사입.출고현황!$B:$H,G$182,0),0) -> Sup't | H43: =IFERROR(VLOOKUP($F43,본공사입.출고현황!$B:$H,H$182,0),0) -> Angle 50x50x5 | I43: =IFERROR(VLOOKUP($F43,본공사입.출고현황!$B:$H,I$182,0),0) -> Angle | J43: =IFERROR(VLOOKUP($F43,본공사입.출고현황!$B:$H,J$182,0),0) -> 50*50*5 | K43: =IFERROR(VLOOKUP($F43,본공사입.출고현황!$B:$H,K$182,0),0) -> M | L43: 200
A44: 6 | B44: 6 | C44: 수기 | E44: 45340 | F44: CO017 | G44: =IFERROR(VLOOKUP($F44,본공사입.출고현황!$B:$H,G$182,0),0) -> Sup't | H44: =IFERROR(VLOOKUP($F44,본공사입.출고현황!$B:$H,H$182,0),0) -> Angle 70x70x7 | I44: =IFERROR(VLOOKUP($F44,본공사입.출고현황!$B:$H,I$182,0),0) -> Angle | J44: =IFERROR(VLOOKUP($F44,본공사입.출고현황!$B:$H,J$182,0),0) -> 70*70*7 | K44: =IFERROR(VLOOKUP($F44,본공사입.출고현황!$B:$H,K$182,0),0) -> M | L44: 40
A45: 7 | B45: 7 | C45: 수기 | E45: 45348 | F45: CO016 | G45: =IFERROR(VLOOKUP($F45,본공사입.출고현황!$B:$H,G$182,0),0) -> Sup't | H45: =IFERROR(VLOOKUP($F45,본공사입.출고현황!$B:$H,H$182,0),0) -> Angle 50x50x5 | I45: =IFERROR(VLOOKUP($F45,본공사입.출고현황!$B:$H,I$182,0),0) -> Angle | J45: =IFERROR(VLOOKUP($F45,본공사입.출고현황!$B:$H,J$182,0),0) -> 50*50*5 | K45: =IFERROR(VLOOKUP($F45,본공사입.출고현황!$B:$H,K$182,0),0) -> M | L45: 384
A46: 8 | B46: 8 | C46: 수기 | E46: 45344 | F46: CO013 | G46: =IFERROR(VLOOKUP($F46,본공사입.출고현황!$B:$H,G$182,0),0) -> Conduit Fitting | H46: =IFERROR(VLOOKUP($F46,본공사입.출고현황!$B:$H,H$182,0),0) -> Conduit Coupling 121x5 | I46: =IFERROR(VLOOKUP($F46,본공사입.출고현황!$B:$H,I$182,0),0) -> Conduit Coupling | J46: =IFERROR(VLOOKUP($F46,본공사입.출고현황!$B:$H,J$182,0),0) -> 121x5 | K46: =IFERROR(VLOOKUP($F46,본공사입.출고현황!$B:$H,K$182,0),0) -> EA | L46: 20
A47: 9 | B47: 9 | C47: 수기 | E47: 45344 | F47: CO010 | G47: =IFERROR(VLOOKUP($F47,본공사입.출고현황!$B:$H,G$182,0),0) -> Conduit Fitting | H47: =IFERROR(VLOOKUP($F47,본공사입.출고현황!$B:$H,H$182,0),0) -> Conduit Coupling 168x4 | I47: =IFERROR(VLOOKUP($F47,본공사입.출고현황!$B:$H,I$182,0),0) -> Conduit Coupling | J47: =IFERROR(VLOOKUP($F47,본공사입.출고현황!$B:$H,J$182,0),0) -> 168x4 | K47: =IFERROR(VLOOKUP($F47,본공사입.출고현황!$B:$H,K$182,0),0) -> EA | L47: 20
A48: 10 | B48: 10 | C48: 수기 | E48: 45364 | F48: CO013 | G48: =IFERROR(VLOOKUP($F48,본공사입.출고현황!$B:$H,G$182,0),0) -> Conduit Fitting | H48: =IFERROR(VLOOKUP($F48,본공사입.출고현황!$B:$H,H$182,0),0) -> Conduit Coupling 121x5 | I48: =IFERROR(VLOOKUP($F48,본공사입.출고현황!$B:$H,I$182,0),0) -> Conduit Coupling | J48: =IFERROR(VLOOKUP($F48,본공사입.출고현황!$B:$H,J$182,0),0) -> 121x5 | K48: =IFERROR(VLOOKUP($F48,본공사입.출고현황!$B:$H,K$182,0),0) -> EA | L48: 30
A49: 11 | B49: 11 | C49: 수기 | E49: 45364 | F49: CO010 | G49: =IFERROR(VLOOKUP($F49,본공사입.출고현황!$B:$H,G$182,0),0) -> Conduit Fitting | H49: =IFERROR(VLOOKUP($F49,본공사입.출고현황!$B:$H,H$182,0),0) -> Conduit Coupling 168x4 | I49: =IFERROR(VLOOKUP($F49,본공사입.출고현황!$B:$H,I$182,0),0) -> Conduit Coupling | J49: =IFERROR(VLOOKUP($F49,본공사입.출고현황!$B:$H,J$182,0),0) -> 168x4 | K49: =IFERROR(VLOOKUP($F49,본공사입.출고현황!$B:$H,K$182,0),0) -> EA | L49: 20
A50: 12 | B50: 12 | C50: 수기 | E50: 45371 | F50: GR005 | G50: =IFERROR(VLOOKUP($F50,본공사입.출고현황!$B:$H,G$182,0),0) -> Ground | H50: =IFERROR(VLOOKUP($F50,본공사입.출고현황!$B:$H,H$182,0),0) -> Cadweld Powder #115 | I50: =IFERROR(VLOOKUP($F50,본공사입.출고현황!$B:$H,I$182,0),0) -> Cadweld Powder | J50: =IFERROR(VLOOKUP($F50,본공사입.출고현황!$B:$H,J$182,0),0) -> #115 | K50: =IFERROR(VLOOKUP($F50,본공사입.출고현황!$B:$H,K$182,0),0) -> EA | L50: 21
... A73: 35 | B73: 35 | C73: 수기 | E73: 45449 | F73: CO002 | G73: =IFERROR(VLOOKUP($F73,본공사입.출고현황!$B:$H,G$182,0),0) -> Conduit | H73: =IFERROR(VLOOKUP($F73,본공사입.출고현황!$B:$H,H$182,0),0) -> Conduit (Galvanized) Ts-80x4 | I73: =IFERROR(VLOOKUP($F73,본공사입.출고현황!$B:$H,I$182,0),0) -> Conduit (Galvanized) | J73: =IFERROR(VLOOKUP($F73,본공사입.출고현황!$B:$H,J$182,0),0) -> 88x4 | K73: =IFERROR(VLOOKUP($F73,본공사입.출고현황!$B:$H,K$182,0),0) -> M | L73: 252
A74: 36 | B74: 36 | C74: 수기 | D74: 9-072-D-450-1020-E /9-072-D-450-1018-E | E74: 45467 | F74: GR014 | G74: =IFERROR(VLOOKUP($F74,본공사입.출고현황!$B:$H,G$182,0),0) -> PVC PIPE | H74: =IFERROR(VLOOKUP($F74,본공사입.출고현황!$B:$H,H$182,0),0) -> PVC Flexible Pipe ф 20 | I74: =IFERROR(VLOOKUP($F74,본공사입.출고현황!$B:$H,I$182,0),0) -> PVC PIPE | J74: =IFERROR(VLOOKUP($F74,본공사입.출고현황!$B:$H,J$182,0),0) -> ф20 | K74: =IFERROR(VLOOKUP($F74,본공사입.출고현황!$B:$H,K$182,0),0) -> M | L74: 140
A75: 37 | B75: 37 | C75: 수기 | E75: 45449 | F75: GR003 | G75: =IFERROR(VLOOKUP($F75,본공사입.출고현황!$B:$H,G$182,0),0) -> Ground Fitting | H75: =IFERROR(VLOOKUP($F75,본공사입.출고현황!$B:$H,H$182,0),0) -> Ground TERMINAL LUG 70mm2 | I75: =IFERROR(VLOOKUP($F75,본공사입.출고현황!$B:$H,I$182,0),0) -> Terminal Lug | J75: =IFERROR(VLOOKUP($F75,본공사입.출고현황!$B:$H,J$182,0),0) -> 70mm2 | K75: =IFERROR(VLOOKUP($F75,본공사입.출고현황!$B:$H,K$182,0),0) -> EA | L75: 200
A76: 38 | B76: 38 | C76: 수기 | E76: 45449 | F76: CO015 | G76: =IFERROR(VLOOKUP($F76,본공사입.출고현황!$B:$H,G$182,0),0) -> Conduit Fitting | H76: =IFERROR(VLOOKUP($F76,본공사입.출고현황!$B:$H,H$182,0),0) -> Conduit Coupling 80-Ts | I76: =IFERROR(VLOOKUP($F76,본공사입.출고현황!$B:$H,I$182,0),0) -> Conduit Coupling | J76: =IFERROR(VLOOKUP($F76,본공사입.출고현황!$B:$H,J$182,0),0) -> 80-Ts | K76: =IFERROR(VLOOKUP($F76,본공사입.출고현황!$B:$H,K$182,0),0) -> EA | L76: 10
A77: 39 | B77: 39 | C77: 수기 | E77: 45469 | F77: CO007 | G77: =IFERROR(VLOOKUP($F77,본공사입.출고현황!$B:$H,G$182,0),0) -> Conduit | H77: =IFERROR(VLOOKUP($F77,본공사입.출고현황!$B:$H,H$182,0),0) -> Conduit 108x4.0 | I77: =IFERROR(VLOOKUP($F77,본공사입.출고현황!$B:$H,I$182,0),0) -> Conduit | J77: =IFERROR(VLOOKUP($F77,본공사입.출고현황!$B:$H,J$182,0),0) -> 108x4 | K77: =IFERROR(VLOOKUP($F77,본공사입.출고현황!$B:$H,K$182,0),0) -> M | L77: 847
A78: 40 | B78: 40 | C78: 수기 | E78: 45469 | F78: CO012 | G78: =IFERROR(VLOOKUP($F78,본공사입.출고현황!$B:$H,G$182,0),0) -> Conduit Fitting | H78: =IFERROR(VLOOKUP($F78,본공사입.출고현황!$B:$H,H$182,0),0) -> Conduit Coupling 121x5 | I78: =IFERROR(VLOOKUP($F78,본공사입.출고현황!$B:$H,I$182,0),0) -> Conduit Coupling | J78: =IFERROR(VLOOKUP($F78,본공사입.출고현황!$B:$H,J$182,0),0) -> 121x5 | K78: =IFERROR(VLOOKUP($F78,본공사입.출고현황!$B:$H,K$182,0),0) -> M | L78: 84
A79: 41 | B79: 41 | C79: 수기 | E79: 45469 | F79: GR002 | G79: =IFERROR(VLOOKUP($F79,본공사입.출고현황!$B:$H,G$182,0),0) -> Ground | H79: =IFERROR(VLOOKUP($F79,본공사입.출고현황!$B:$H,H$182,0),0) -> Ground Cable 70SQ | I79: =IFERROR(VLOOKUP($F79,본공사입.출고현황!$B:$H,I$182,0),0) -> Ground Cable | J79: =IFERROR(VLOOKUP($F79,본공사입.출고현황!$B:$H,J$182,0),0) -> 70SQ | K79: =IFERROR(VLOOKUP($F79,본공사입.출고현황!$B:$H,K$182,0),0) -> M | L79: 3120
A80: 42 | B80: 42 | C80: 수기 | E80: 45469 | F80: CO002 | G80: =IFERROR(VLOOKUP($F80,본공사입.출고현황!$B:$H,G$182,0),0) -> Conduit | H80: =IFERROR(VLOOKUP($F80,본공사입.출고현황!$B:$H,H$182,0),0) -> Conduit (Galvanized) Ts-80x4 | I80: =IFERROR(VLOOKUP($F80,본공사입.출고현황!$B:$H,I$182,0),0) -> Conduit (Galvanized) | J80: =IFERROR(VLOOKUP($F80,본공사입.출고현황!$B:$H,J$182,0),0) -> 88x4 | K80: =IFERROR(VLOOKUP($F80,본공사입.출고현황!$B:$H,K$182,0),0) -> M | L80: 864
A81: 43 | B81: 43 | C81: 수기 | E81: 45495 | F81: GR007 | G81: =IFERROR(VLOOKUP($F81,본공사입.출고현황!$B:$H,G$182,0),0) -> Ground | H81: =IFERROR(VLOOKUP($F81,본공사입.출고현황!$B:$H,H$182,0),0) -> Cadweld Powder #200 | I81: =IFERROR(VLOOKUP($F81,본공사입.출고현황!$B:$H,I$182,0),0) -> Cadweld Powder | J81: =IFERROR(VLOOKUP($F81,본공사입.출고현황!$B:$H,J$182,0),0) -> #200 | K81: =IFERROR(VLOOKUP($F81,본공사입.출고현황!$B:$H,K$182,0),0) -> EA | L81: 600
A82: 44 | B82: 44 | C82: 수기 | E82: 45495 | F82: GR005 | G82: =IFERROR(VLOOKUP($F82,본공사입.출고현황!$B:$H,G$182,0),0) -> Ground | H82: =IFERROR(VLOOKUP($F82,본공사입.출고현황!$B:$H,H$182,0),0) -> Cadweld Powder #115 | I82: =IFERROR(VLOOKUP($F82,본공사입.출고현황!$B:$H,I$182,0),0) -> Cadweld Powder | J82: =IFERROR(VLOOKUP($F82,본공사입.출고현황!$B:$H,J$182,0),0) -> #115 | K82: =IFERROR(VLOOKUP($F82,본공사입.출고현황!$B:$H,K$182,0),0) -> EA | L82: 150
...

Sheet POR Control Log-out
B1: POR CONTROL LOG - Issue
B2: 【Project : El-Dabaa Nuclear Power Plant (ENPP) #1 to 4】 | H2: from Warehouse & Workshop to Site
B3: No | C3: Date | D3: Material No. | E3: Sortation | F3: Items / Services | G3: Applicable Code & Standards | H3: Size | I3: Unit | J3: Unit # | K3: BLDG | L3: Q'TY | M3: User | N3: Remarks
B5: 1 | C5: 2024이전사용분 | D5: GR001 | E5: =IFERROR(VLOOKUP($D5,본공사입.출고현황!$B:$H,E$2080,0),0) -> Ground | F5: =IFERROR(VLOOKUP($D5,본공사입.출고현황!$B:$H,F$2080,0),0) -> Ground Cable 78SQ | G5: =IFERROR(VLOOKUP($D5,본공사입.출고현황!$B:$H,G$2080,0),0) -> Ground Cable | H5: =IFERROR(VLOOKUP($D5,본공사입.출고현황!$B:$H,H$2080,0),0) -> 78SQ | I5: =IFERROR(VLOOKUP($D5,본공사입.출고현황!$B:$H,I$2080,0),0) -> M | L5: 12796.6
B6: 2 | C6: 2024이전사용분 | D6: GR002 | E6: =IFERROR(VLOOKUP($D6,본공사입.출고현황!$B:$H,E$2080,0),0) -> Ground | F6: =IFERROR(VLOOKUP($D6,본공사입.출고현황!$B:$H,F$2080,0),0) -> Ground Cable 70SQ | G6: =IFERROR(VLOOKUP($D6,본공사입.출고현황!$B:$H,G$2080,0),0) -> Ground Cable | H6: =IFERROR(VLOOKUP($D6,본공사입.출고현황!$B:$H,H$2080,0),0) -> 70SQ | I6: =IFERROR(VLOOKUP($D6,본공사입.출고현황!$B:$H,I$2080,0),0) -> M | L6: 18
B7: 3 | C7: 2024이전사용분 | D7: GR003 | E7: =IFERROR(VLOOKUP($D7,본공사입.출고현황!$B:$H,E$2080,0),0) -> Ground Fitting | F7: =IFERROR(VLOOKUP($D7,본공사입.출고현황!$B:$H,F$2080,0),0) -> Ground TERMINAL LUG 70mm2 | G7: =IFERROR(VLOOKUP($D7,본공사입.출고현황!$B:$H,G$2080,0),0) -> Terminal Lug | H7: =IFERROR(VLOOKUP($D7,본공사입.출고현황!$B:$H,H$2080,0),0) -> 70mm2 | I7: =IFERROR(VLOOKUP($D7,본공사입.출고현황!$B:$H,I$2080,0),0) -> EA | L7: 9
B8: 4 | C8: 2024이전사용분 | D8: GR004 | E8: =IFERROR(VLOOKUP($D8,본공사입.출고현황!$B:$H,E$2080,0),0) -> Ground | F8: =IFERROR(VLOOKUP($D8,본공사입.출고현황!$B:$H,F$2080,0),0) -> Cadweld Powder #90 | G8: =IFERROR(VLOOKUP($D8,본공사입.출고현황!$B:$H,G$2080,0),0) -> Cadweld Powder | H8: =IFERROR(VLOOKUP($D8,본공사입.출고현황!$B:$H,H$2080,0),0) -> #90 | I8: =IFERROR(VLOOKUP($D8,본공사입.출고현황!$B:$H,I$2080,0),0) -> EA | L8: 5
B9: 5 | C9: 2024이전사용분 | D9: GR005 | E9: =IFERROR(VLOOKUP($D9,본공사입.출고현황!$B:$H,E$2080,0),0) -> Ground | F9: =IFERROR(VLOOKUP($D9,본공사입.출고현황!$B:$H,F$2080,0),0) -> Cadweld Powder #115 | G9: =IFERROR(VLOOKUP($D9,본공사입.출고현황!$B:$H,G$2080,0),0) -> Cadweld Powder | H9: =IFERROR(VLOOKUP($D9,본공사입.출고현황!$B:$H,H$2080,0),0) -> #115 | I9: =IFERROR(VLOOKUP($D9,본공사입.출고현황!$B:$H,I$2080,0),0) -> EA | L9: 94
B10: 6 | C10: 2024이전사용분 | D10: GR006 | E10: =IFERROR(VLOOKUP($D10,본공사입.출고현황!$B:$H,E$2080,0),0) -> Ground | F10: =IFERROR(VLOOKUP($D10,본공사입.출고현황!$B:$H,F$2080,0),0) -> Cadweld Powder #150 | G10: =IFERROR(VLOOKUP($D10,본공사입.출고현황!$B:$H,G$2080,0),0) -> Cadweld Powder | H10: =IFERROR(VLOOKUP($D10,본공사입.출고현황!$B:$H,H$2080,0),0) -> #150 | I10: =IFERROR(VLOOKUP($D10,본공사입.출고현황!$B:$H,I$2080,0),0) -> EA | L10: 2
B11: 7 | C11: 2024이전사용분 | D11: GR007 | E11: =IFERROR(VLOOKUP($D11,본공사입.출고현황!$B:$H,E$2080,0),0) -> Ground | F11: =IFERROR(VLOOKUP($D11,본공사입.출고현황!$B:$H,F$2080,0),0) -> Cadweld Powder #200 | G11: =IFERROR(VLOOKUP($D11,본공사입.출고현황!$B:$H,G$2080,0),0) -> Cadweld Powder | H11: =IFERROR(VLOOKUP($D11,본공사입.출고현황!$B:$H,H$2080,0),0) -> #200 | I11: =IFERROR(VLOOKUP($D11,본공사입.출고현황!$B:$H,I$2080,0),0) -> EA | L11: 678
B12: 8 | C12: 2024이전사용분 | D12: GR008 | E12: =IFERROR(VLOOKUP($D12,본공사입.출고현황!$B:$H,E$2080,0),0) -> Ground | F12: =IFERROR(VLOOKUP($D12,본공사입.출고현황!$B:$H,F$2080,0),0) -> Cadweld XBQ-Y4Y4 | G12: =IFERROR(VLOOKUP($D12,본공사입.출고현황!$B:$H,G$2080,0),0) -> Welding Mold | H12: =IFERROR(VLOOKUP($D12,본공사입.출고현황!$B:$H,H$2080,0),0) -> Cross (+) | I12: =IFERROR(VLOOKUP($D12,본공사입.출고현황!$B:$H,I$2080,0),0) -> EA | L12: 12
B13: 9 | C13: 2024이전사용분 | D13: GR009 | E13: =IFERROR(VLOOKUP($D13,본공사입.출고현황!$B:$H,E$2080,0),0) -> Ground | F13: =IFERROR(VLOOKUP($D13,본공사입.출고현황!$B:$H,F$2080,0),0) -> Cadweld PGC-Y4Y4 | G13: =IFERROR(VLOOKUP($D13,본공사입.출고현황!$B:$H,G$2080,0),0) -> Welding Mold | H13: =IFERROR(VLOOKUP($D13,본공사입.출고현황!$B:$H,H$2080,0),0) -> Parallel (=) | I13: =IFERROR(VLOOKUP($D13,본공사입.출고현황!$B:$H,I$2080,0),0) -> EA | L13: 0
B14: 10 | C14: 2024이전사용분 | D14: GR010 | E14: =IFERROR(VLOOKUP($D14,본공사입.출고현황!$B:$H,E$2080,0),0) -> Ground | F14: =IFERROR(VLOOKUP($D14,본공사입.출고현황!$B:$H,F$2080,0),0) -> Cadweld TAC-Y4Y4 | G14: =IFERROR(VLOOKUP($D14,본공사입.출고현황!$B:$H,G$2080,0),0) -> Welding Mold | H14: =IFERROR(VLOOKUP($D14,본공사입.출고현황!$B:$H,H$2080,0),0) -> Cross (T) | I14: =IFERROR(VLOOKUP($D14,본공사입.출고현황!$B:$H,I$2080,0),0) -> EA | L14: 1
B15: 11 | C15: 2024이전사용분 | D15: GR011 | E15: =IFERROR(VLOOKUP($D15,본공사입.출고현황!$B:$H,E$2080,0),0) -> Ground | F15: =IFERROR(VLOOKUP($D15,본공사입.출고현황!$B:$H,F$2080,0),0) -> Zinc Spray | G15: =IFERROR(VLOOKUP($D15,본공사입.출고현황!$B:$H,G$2080,0),0) -> Zinc Spray | H15: =IFERROR(VLOOKUP($D15,본공사입.출고현황!$B:$H,H$2080,0),0) -> 0 | I15: =IFERROR(VLOOKUP($D15,본공사입.출고현황!$B:$H,I$2080,0),0) -> EA | L15: 87
B16: 12 | C16: 2024이전사용분 | D16: GR012 | E16: =IFERROR(VLOOKUP($D16,본공사입.출고현황!$B:$H,E$2080,0),0) -> Miscellious | F16: =IFERROR(VLOOKUP($D16,본공사입.출고현황!$B:$H,F$2080,0),0) -> Nicoband | G16: =IFERROR(VLOOKUP($D16,본공사입.출고현황!$B:$H,G$2080,0),0) -> Nicoband | H16: =IFERROR(VLOOKUP($D16,본공사입.출고현황!$B:$H,H$2080,0),0) -> 10m x 15cm | I16: =IFERROR(VLOOKUP($D16,본공사입.출고현황!$B:$H,I$2080,0),0) -> EA | L16: 0
... B42: 39 | C42: 2024이전사용분 | D42: CG001 | E42: =IFERROR(VLOOKUP($D42,본공사입.출고현황!$B:$H,E$2080,0),0) -> Steel round bar | F42: =IFERROR(VLOOKUP($D42,본공사입.출고현황!$B:$H,F$2080,0),0) -> Steel round bar(rebar) | G42: =IFERROR(VLOOKUP($D42,본공사입.출고현황!$B:$H,G$2080,0),0) -> CCGG | H42: =IFERROR(VLOOKUP($D42,본공사입.출고현황!$B:$H,H$2080,0),0) -> ф10, 1ton=1,620.7m | I42: =IFERROR(VLOOKUP($D42,본공사입.출고현황!$B:$H,I$2080,0),0) -> M | L42: 4181.6
B43: 40 | C43: 2024이전사용분 | D43: CG002 | E43: =IFERROR(VLOOKUP($D43,본공사입.출고현황!$B:$H,E$2080,0),0) -> Angle | F43: =IFERROR(VLOOKUP($D43,본공사입.출고현황!$B:$H,F$2080,0),0) -> Angle 100x100x10 | G43: =IFERROR(VLOOKUP($D43,본공사입.출고현황!$B:$H,G$2080,0),0) -> CCGG | H43: =IFERROR(VLOOKUP($D43,본공사입.출고현황!$B:$H,H$2080,0),0) -> 100x100x10 (12m) | I43: =IFERROR(VLOOKUP($D43,본공사입.출고현황!$B:$H,I$2080,0),0) -> M | L43: 385 | O43: 444 | P43: =L43+O43 -> 829
A44: 1 | B44: 1 | C44: 45658 | D44: CO018 | E44: =IFERROR(VLOOKUP($D44,본공사입.출고현황!$B:$H,E$2080,0),0) -> Sup't | F44: =IFERROR(VLOOKUP($D44,본공사입.출고현황!$B:$H,F$2080,0),0) -> Angle 75x75x5 | G44: =IFERROR(VLOOKUP($D44,본공사입.출고현황!$B:$H,G$2080,0),0) -> Angle | H44: =IFERROR(VLOOKUP($D44,본공사입.출고현황!$B:$H,H$2080,0),0) -> 75x75x5 | I44: =IFERROR(VLOOKUP($D44,본공사입.출고현황!$B:$H,I$2080,0),0) -> M | J44: 2 | K44: 20USJ | L44: 1 | M44: Hussien Elsayed
